Workbook

Sheet 編集用｜昭和ろまん
A1: アセスメントシート | N1: {=IFERROR( INDEX(データ集約!A:ZZ, MATCH(D6, データ集約!C:C, 0), MATCH("事業所の選択", データ集約!1:1, 0)), "" )} | AA1: 作成年月日： | AF1: {=IFERROR( INDEX(データ集約!A:ZZ, MATCH(D6, データ集約!C:C, 0), MATCH("作成日", データ集約!1:1, 0)), "" )}
X2: 入居予定日： | AD2: {=IFERROR( INDEX(データ集約!A:ZZ, MATCH(D6, データ集約!C:C, 0), MATCH("入居予定日", データ集約!1:1, 0)), "" )}
A4: アセスメントの理由 | G4: {=IFERROR( INDEX(データ集約!A:ZZ, MATCH(D6, データ集約!C:C, 0), MATCH("アセスメントの理由", データ集約!1:1, 0)), "" )} | R4: 面談場所 | U4: {=IFERROR( INDEX(データ集約!A:ZZ, MATCH(D6, データ集約!C:C, 0), MATCH("面談場所", データ集約!1:1, 0)), "" )} | AD4: 作成者 | AG4: {=IFERROR( INDEX(データ集約!A:ZZ, MATCH(D6, データ集約!C:C, 0), MATCH("作成者", データ集約!1:1, 0)), "" )}
A5: 基本事項 | B5: ふりがな | D5: {=IFERROR( INDEX(利用者一覧!A:I, MATCH(D6, 利用者一覧!C:C, 0), MATCH("氏名（ふりがな）", 利用者一覧!1:1, 0)), "" )} | R5: 性別 | X5: 生年月日 | AD5: 年齢
B6: 氏名 | D6: 「利用者」を選択してください。 | P6: 様 | R6: {=IFERROR( INDEX(利用者一覧!A:I, MATCH(D6, 利用者一覧!C:C, 0), MATCH("性別", 利用者一覧!1:1, 0)), "" )} | X6: {=IFERROR( INDEX(利用者一覧!A:I, MATCH(D6, 利用者一覧!C:C, 0), MATCH("生年月日", 利用者一覧!1:1, 0)), "" )} | AD6: =IFERROR( DATEDIF( DATE( IF(LEFT(X6, 2) = "令和", 2018 + MID(X6, 3, FIND("年", X6) - 3), IF(LEFT(X6, 2) = "平成", 1988 + MID(X6, 3, FIND("年", X6) - 3), IF(LEFT(X6, 2) = "昭和", 1925 + MID(X6, 3, FIND("年", X6) - 3), IF(LEFT(X6, 2) = "大正", 1911 + MID(X6, 3, FIND("年", X6) - 3), IF(LEFT(X6, 2) = "明治", 1867 + MID(X6, 3, FIND("年", X6) - 3), 0))))), MID(X6, FIND("年", X6) + 1, FIND("月", X6) - FIND("年", X6) - 1), MID(X6, FIND("月", X6) + 1, FIND("日", X6) - FIND("月", X6) - 1) ), TODAY(), "Y" ), "" ) | AJ6: 歳
B8: 住所 | D8: {=IFERROR( INDEX(利用者一覧!A:I, MATCH(D6, 利用者一覧!C:C, 0), MATCH("住所", 利用者一覧!1:1, 0)), "" )} | AA8: 連絡先 | AD8: {=IFERROR( INDEX(利用者一覧!A:I, MATCH(D6, 利用者一覧!C:C, 0), MATCH("連絡先", 利用者一覧!1:1, 0)), "" )}
A10: 保険情報 | B10: 介護保険 | E10: 被保険者番号 | J10: 要介護度 | Q10: 認定日 | V10: 認定期間 | AI10: 負担割合
E11: {=IFERROR( INDEX(利用者一覧!A:I, MATCH(D6, 利用者一覧!C:C, 0), MATCH("利用者ID（被保険者番号）", 利用者一覧!1:1, 0)), "" )} | J11: {=IFERROR( INDEX(データ集約!A:ZZ, MATCH(D6, データ集約!C:C, 0), MATCH("要介護度", データ集約!1:1, 0)), "" )} | Q11: {=IFERROR( INDEX(データ集約!A:ZZ, MATCH(D6, データ集約!C:C, 0), MATCH("認定日", データ集約!1:1, 0)), "" )} | V11: {=IFERROR( INDEX(データ集約!A:ZZ, MATCH(D6, データ集約!C:C, 0), MATCH("認定期間｜開始", データ集約!1:1, 0)), "" )} | AB11: ～ | AC11: {=IFERROR( INDEX(データ集約!A:ZZ, MATCH(D6, データ集約!C:C, 0), MATCH("認定期間｜終了", データ集約!1:1, 0)), "" )} | AI11: {=IFERROR( INDEX(データ集約!A:ZZ, MATCH(D6, データ集約!C:C, 0), MATCH("負担割合", データ集約!1:1, 0)), "" )}
B13: 医療保険 | M13: 身体障害者手帳 | R13: 難病申請 | V13: 生活保護 | Z13: 障害者日常生活自立度 | AF13: 認知症日常生活自立度
B14: {=IFERROR( INDEX(データ集約!A:ZZ, MATCH(D6, データ集約!C:C, 0), MATCH("医療保険", データ集約!1:1, 0)), "" )} | M14: {=IFERROR( INDEX(データ集約!A:ZZ, MATCH(D6, データ集約!C:C, 0), MATCH("身体障がい者手帳の有無", データ集約!1:1, 0)), "" )} | O14: {=IFERROR( INDEX(データ集約!A:ZZ, MATCH(D6, データ集約!C:C, 0), MATCH("種類", データ集約!1:1, 0)), "" )} | R14: {=IFERROR( INDEX(データ集約!A:ZZ, MATCH(D6, データ集約!C:C, 0), MATCH("難病申請", データ集約!1:1, 0)), "" )} | V14: {=IFERROR( INDEX(データ集約!A:ZZ, MATCH(D6, データ集約!C:C, 0), MATCH("生活保護", データ集約!1:1, 0)), "" )} | Z14: {=IFERROR( INDEX(データ集約!A:ZZ, MATCH(D6, データ集約!C:C, 0), MATCH("障がい者日常生活自立度", データ集約!1:1, 0)), "" )} | AF14: {=IFERROR( INDEX(データ集約!A:ZZ, MATCH(D6, データ集約!C:C, 0), MATCH("認知症日常生活自立度", データ集約!1:1, 0)), "" )}
A16: 家族状況 | B16: 家族氏名 | K16: 続柄 | O16: 同居有無 | R16: 介護 | V16: 就労 | Z16: 連絡先 | AF16: 備考（KP等）
B17: ① | D17: {=IFERROR( INDEX(データ集約!A:ZZ, MATCH(D6, データ集約!C:C, 0), MATCH("家族氏名-1", データ集約!1:1, 0)), "" )} | J17: 様 | K17: {=IFERROR( INDEX(データ集約!A:ZZ, MATCH(D6, データ集約!C:C, 0), MATCH("続柄-1", データ集約!1:1, 0)), "" )} | O17: {=IFERROR( INDEX(データ集約!A:ZZ, MATCH(D6, データ集約!C:C, 0), MATCH("同居有無-1", データ集約!1:1, 0)), "" )} | R17: {=IFERROR( INDEX(データ集約!A:ZZ, MATCH(D6, データ集約!C:C, 0), MATCH("介護-1", データ集約!1:1, 0)), "" )} | V17: {=IFERROR( INDEX(データ集約!A:ZZ, MATCH(D6, データ集約!C:C, 0), MATCH("就労-1", データ集約!1:1, 0)), "" )} | Z17: {=IFERROR( INDEX(データ集約!A:ZZ, MATCH(D6, データ集約!C:C, 0), MATCH("連絡先-1", データ集約!1:1, 0)), "" )} | AF17: {=IFERROR( INDEX(データ集約!A:ZZ, MATCH(D6, データ集約!C:C, 0), MATCH("備考-1", データ集約!1:1, 0)), "" )}
B19: ② | D19: {=IFERROR( INDEX(データ集約!A:ZZ, MATCH(D6, データ集約!C:C, 0), MATCH("家族氏名-2", データ集約!1:1, 0)), "" )} | J19: 様 | K19: {=IFERROR( INDEX(データ集約!A:ZZ, MATCH(D6, データ集約!C:C, 0), MATCH("続柄-2", データ集約!1:1, 0)), "" )} | O19: {=IFERROR( INDEX(データ集約!A:ZZ, MATCH(D6, データ集約!C:C, 0), MATCH("同居有無-2", データ集約!1:1, 0)), "" )} | R19: {=IFERROR( INDEX(データ集約!A:ZZ, MATCH(D6, データ集約!C:C, 0), MATCH("介護-2", データ集約!1:1, 0)), "" )} | V19: {=IFERROR( INDEX(データ集約!A:ZZ, MATCH(D6, データ集約!C:C, 0), MATCH("就労-2", データ集約!1:1, 0)), "" )} | Z19: {=IFERROR( INDEX(データ集約!A:ZZ, MATCH(D6, データ集約!C:C, 0), MATCH("連絡先-2", データ集約!1:1, 0)), "" )} | AF19: {=IFERROR( INDEX(データ集約!A:ZZ, MATCH(D6, データ集約!C:C, 0), MATCH("備考-2", データ集約!1:1, 0)), "" )}
A21: 健康状態 | B21: 疾患名 | N21: 発症日 | S21: 診療機関 | Z21: 既往
B22: {=IFERROR( INDEX(データ集約!A:ZZ, MATCH(D6, データ集約!C:C, 0), MATCH("疾患名-1", データ集約!1:1, 0)), "" )} | N22: {=IFERROR( INDEX(データ集約!A:ZZ, MATCH(D6, データ集約!C:C, 0), MATCH("発症日-1", データ集約!1:1, 0)), "" )} | S22: {=IFERROR( INDEX(データ集約!A:ZZ, MATCH(D6, データ集約!C:C, 0), MATCH("診療機関-1", データ集約!1:1, 0)), "" )} | Z22: {=IFERROR( INDEX(データ集約!A:ZZ, MATCH(D6, データ集約!C:C, 0), MATCH("既往歴", データ集約!1:1, 0)), "" )}
B24: {=IFERROR( INDEX(データ集約!A:ZZ, MATCH(D6, データ集約!C:C, 0), MATCH("疾患名-2", データ集約!1:1, 0)), "" )} | N24: {=IFERROR( INDEX(データ集約!A:ZZ, MATCH(D6, データ集約!C:C, 0), MATCH("発症日-2", データ集約!1:1, 0)), "" )} | S24: {=IFERROR( INDEX(データ集約!A:ZZ, MATCH(D6, データ集約!C:C, 0), MATCH("診療機関-2", データ集約!1:1, 0)), "" )}
B26: {=IFERROR( INDEX(データ集約!A:ZZ, MATCH(D6, データ集約!C:C, 0), MATCH("疾患名-3", データ集約!1:1, 0)), "" )} | N26: {=IFERROR( INDEX(データ集約!A:ZZ, MATCH(D6, データ集約!C:C, 0), MATCH("発症日-3", データ集約!1:1, 0)), "" )} | S26: {=IFERROR( INDEX(データ集約!A:ZZ, MATCH(D6, データ集約!C:C, 0), MATCH("診療機関-3", データ集約!1:1, 0)), "" )} | Z26: 通院
Z27: {=IFERROR( INDEX(データ集約!A:ZZ, MATCH(D6, データ集約!C:C, 0), MATCH("通院", データ集約!1:1, 0)), "" )}
B28: {=IFERROR( INDEX(データ集約!A:ZZ, MATCH(D6, データ集約!C:C, 0), MATCH("疾患名-4", データ集約!1:1, 0)), "" )} | N28: {=IFERROR( INDEX(データ集約!A:ZZ, MATCH(D6, データ集約!C:C, 0), MATCH("発症日-4", データ集約!1:1, 0)), "" )} | S28: {=IFERROR( INDEX(データ集約!A:ZZ, MATCH(D6, データ集約!C:C, 0), MATCH("診療機関-4", データ集約!1:1, 0)), "" )}
B30: {=IFERROR( INDEX(データ集約!A:ZZ, MATCH(D6, データ集約!C:C, 0), MATCH("疾患名-5", データ集約!1:1, 0)), "" )} | N30: {=IFERROR( INDEX(データ集約!A:ZZ, MATCH(D6, データ集約!C:C, 0), MATCH("発症日-5", データ集約!1:1, 0)), "" )} | S30: {=IFERROR( INDEX(データ集約!A:ZZ, MATCH(D6, データ集約!C:C, 0), MATCH("診療機関-5", データ集約!1:1, 0)), "" )} | Z30: 服薬
Z31: 眠剤 | AB31: {=IFERROR( INDEX(データ集約!A:ZZ, MATCH(D6, データ集約!C:C, 0), MATCH("服薬｜眠剤の有無", データ集約!1:1, 0)), "" )} | AF31: 下剤 | AH31: {=IFERROR( INDEX(データ集約!A:ZZ, MATCH(D6, データ集約!C:C, 0), MATCH("服薬｜下剤の有無", データ集約!1:1, 0)), "" )}
B32: {=IFERROR( INDEX(データ集約!A:ZZ, MATCH(D6, データ集約!C:C, 0), MATCH("疾患名-6", データ集約!1:1, 0)), "" )} | N32: {=IFERROR( INDEX(データ集約!A:ZZ, MATCH(D6, データ集約!C:C, 0), MATCH("発症日-6", データ集約!1:1, 0)), "" )} | S32: {=IFERROR( INDEX(データ集約!A:ZZ, MATCH(D6, データ集約!C:C, 0), MATCH("診療機関-6", データ集約!1:1, 0)), "" )} | Z32: {=IFERROR( INDEX(データ集約!A:ZZ, MATCH(D6, データ集約!C:C, 0), MATCH("服薬", データ集約!1:1, 0)), "" )}
B34: コロナワクチン接種状況 | N34: {=IFERROR( INDEX(データ集約!A:ZZ, MATCH(D6, データ集約!C:C, 0), MATCH("コロナワクチン接種状況", データ集約!1:1, 0)), "" )} | S34: {=IFERROR( INDEX(データ集約!A:ZZ, MATCH(D6, データ集約!C:C, 0), MATCH("接種回数", データ集約!1:1, 0)), "" )} | X34: =IF(N34="接種済み", "回", "")
A36: 利用サ｜ビス | B36: 介護サービス | F36: {=IFERROR( INDEX(データ集約!A:ZZ, MATCH(D6, データ集約!C:C, 0), MATCH("介護サービス", データ集約!1:1, 0)), "" )} | S36: 福祉用具 | V36: {=IFERROR( INDEX(データ集約!A:ZZ, MATCH(D6, データ集約!C:C, 0), MATCH("福祉用具", データ集約!1:1, 0)), "" )}
S38: その他 | V38: {=IFERROR( INDEX(データ集約!A:ZZ, MATCH(D6, データ集約!C:C, 0), MATCH("その他", データ集約!1:1, 0)), "" )}
B39: インフォーマル サービス | F39: {=IFERROR( INDEX(データ集約!A:ZZ, MATCH(D6, データ集約!C:C, 0), MATCH("インフォーマルサービス", データ集約!1:1, 0)), "" )} | S39: 社会との 関わり | V39: {=IFERROR( INDEX(データ集約!A:ZZ, MATCH(D6, データ集約!C:C, 0), MATCH("社会との関り", データ集約!1:1, 0)), "" )}
A41: 本人の希望 | S41: 家族の希望
A42: {=IFERROR( INDEX(データ集約!A:ZZ, MATCH(D6, データ集約!C:C, 0), MATCH("本人の希望", データ集約!1:1, 0)), "" )} | S42: {=IFERROR( INDEX(データ集約!A:ZZ, MATCH(D6, データ集約!C:C, 0), MATCH("家族の希望", データ集約!1:1, 0)), "" )}
A44: 生活歴 | Z44: 趣味
A45: {=IFERROR( INDEX(データ集約!A:ZZ, MATCH(D6, データ集約!C:C, 0), MATCH("生活歴", データ集約!1:1, 0)), "" )} | Z45: {=IFERROR( INDEX(データ集約!A:ZZ, MATCH(D6, データ集約!C:C, 0), MATCH("趣味", データ集約!1:1, 0)), "" )}
A51: 特記・備考
A52: {=IFERROR( INDEX(データ集約!A:ZZ, MATCH(D6, データ集約!C:C, 0), MATCH("その他、特記事項", データ集約!1:1, 0)), "" )}
A57: ◆ 現在の状況 ◆ | AB57: ◆ 課題分析 ◆
A59: 身体状況 | B59: 皮膚疾患 | I59: {=IFERROR( INDEX(データ集約!A:ZZ, MATCH(D6, データ集約!C:C, 0), MATCH("皮膚疾患", データ集約!1:1, 0)), "" )} | P59: {=IFERROR( INDEX(データ集約!A:ZZ, MATCH(D6, データ集約!C:C, 0), MATCH("身体状況｜特記事項", データ集約!1:1, 0)), "" )}
B60: 感染症 | I60: {=IFERROR( INDEX(データ集約!A:ZZ, MATCH(D6, データ集約!C:C, 0), MATCH("感染症", データ集約!1:1, 0)), "" )}
B61: 特別な医療処置 | I61: {=IFERROR( INDEX(データ集約!A:ZZ, MATCH(D6, データ集約!C:C, 0), MATCH("特別な医療処置", データ集約!1:1, 0)), "" )}
B62: 麻痺 | I62: {=IFERROR( INDEX(データ集約!A:ZZ, MATCH(D6, データ集約!C:C, 0), MATCH("麻痺", データ集約!1:1, 0)), "" )}
B63: 痛み | I63: {=IFERROR( INDEX(データ集約!A:ZZ, MATCH(D6, データ集約!C:C, 0), MATCH("痛み", データ集約!1:1, 0)), "" )}
B64: 身長 | I64: {=IFERROR( INDEX(データ集約!A:ZZ, MATCH(D6, データ集約!C:C, 0), MATCH("身長", データ集約!1:1, 0)), "" )} | N64: cm
B65: 体重 | I65: {=IFERROR( INDEX(データ集約!A:ZZ, MATCH(D6, データ集約!C:C, 0), MATCH("体重", データ集約!1:1, 0)), "" )} | N65: ｋｇ
...

Sheet データ集約
A1: =IFERROR(__xludf.DUMMYFUNCTION("QUERY(IMPORTRANGE(""https://docs.google.com/spreadsheets/d/1oyZMPRie0ZbHoRSApgUTWrLJRtDYMGUGZx5wkotTseU/edit"", ""アセスメントシート（更新用）!A:ZZ""), ""SELECT * WHERE Col10 CONTAINS '山川'"") "),"基本情報") -> 基本情報 | B1: =IFERROR(__xludf.DUMMYFUNCTION("""COMPUTED_VALUE"""),"利用者選択---") -> 利用者選択--- | C1: =IFERROR(__xludf.DUMMYFUNCTION("""COMPUTED_VALUE"""),"利用者名") -> 利用者名 | D1: =IFERROR(__xludf.DUMMYFUNCTION("""COMPUTED_VALUE"""),"利用者ID（被保険者番号）") -> 利用者ID（被保険者番号） | E1: =IFERROR(__xludf.DUMMYFUNCTION("""COMPUTED_VALUE"""),"絞り込み｜担当ケアマネ") -> 絞り込み｜担当ケアマネ | F1: =IFERROR(__xludf.DUMMYFUNCTION("""COMPUTED_VALUE"""),"絞り込み｜頭文字") -> 絞り込み｜頭文字 | G1: =IFERROR(__xludf.DUMMYFUNCTION("""COMPUTED_VALUE"""),"絞り込み") -> 絞り込み | H1: =IFERROR(__xludf.DUMMYFUNCTION("""COMPUTED_VALUE"""),"---利用者選択") -> ---利用者選択 | I1: =IFERROR(__xludf.DUMMYFUNCTION("""COMPUTED_VALUE"""),"作成日") -> 作成日 | J1: =IFERROR(__xludf.DUMMYFUNCTION("""COMPUTED_VALUE"""),"作成者") -> 作成者 | K1: =IFERROR(__xludf.DUMMYFUNCTION("""COMPUTED_VALUE"""),"アセスメントの理由") -> アセスメントの理由 | L1: =IFERROR(__xludf.DUMMYFUNCTION("""COMPUTED_VALUE"""),"面談場所") -> 面談場所 | M1: =IFERROR(__xludf.DUMMYFUNCTION("""COMPUTED_VALUE"""),"生活歴") -> 生活歴 | N1: =IFERROR(__xludf.DUMMYFUNCTION("""COMPUTED_VALUE"""),"本人の希望") -> 本人の希望 | O1: =IFERROR(__xludf.DUMMYFUNCTION("""COMPUTED_VALUE"""),"家族の希望") -> 家族の希望 | P1: =IFERROR(__xludf.DUMMYFUNCTION("""COMPUTED_VALUE"""),"基本情報スペース") -> 基本情報スペース | Q1: =IFERROR(__xludf.DUMMYFUNCTION("""COMPUTED_VALUE"""),"▶保険情報") -> ▶保険情報 | R1: =IFERROR(__xludf.DUMMYFUNCTION("""COMPUTED_VALUE"""),"要介護度") -> 要介護度 | S1: =IFERROR(__xludf.DUMMYFUNCTION("""COMPUTED_VALUE"""),"認定日") -> 認定日 | T1: =IFERROR(__xludf.DUMMYFUNCTION("""COMPUTED_VALUE"""),"認定期間｜開始") -> 認定期間｜開始 | U1: =IFERROR(__xludf.DUMMYFUNCTION("""COMPUTED_VALUE"""),"認定期間｜終了") -> 認定期間｜終了 | V1: =IFERROR(__xludf.DUMMYFUNCTION("""COMPUTED_VALUE"""),"負担割合") -> 負担割合 | W1: =IFERROR(__xludf.DUMMYFUNCTION("""COMPUTED_VALUE"""),"医療保険") -> 医療保険 | X1: =IFERROR(__xludf.DUMMYFUNCTION("""COMPUTED_VALUE"""),"身体障がい者手帳の有無") -> 身体障がい者手帳の有無 | Y1: =IFERROR(__xludf.DUMMYFUNCTION("""COMPUTED_VALUE"""),"種類") -> 種類 | Z1: =IFERROR(__xludf.DUMMYFUNCTION("""COMPUTED_VALUE"""),"難病申請") -> 難病申請 | AA1: =IFERROR(__xludf.DUMMYFUNCTION("""COMPUTED_VALUE"""),"生活保護") -> 生活保護 | AB1: =IFERROR(__xludf.DUMMYFUNCTION("""COMPUTED_VALUE"""),"障がい者日常生活自立度") -> 障がい者日常生活自立度 | AC1: =IFERROR(__xludf.DUMMYFUNCTION("""COMPUTED_VALUE"""),"認知症日常生活自立度") -> 認知症日常生活自立度 | AD1: =IFERROR(__xludf.DUMMYFUNCTION("""COMPUTED_VALUE"""),"←｜保険情報") -> ←｜保険情報 | AE1: =IFERROR(__xludf.DUMMYFUNCTION("""COMPUTED_VALUE"""),"▶家族状況") -> ▶家族状況 | AF1: =IFERROR(__xludf.DUMMYFUNCTION("""COMPUTED_VALUE"""),"家族氏名-1") -> 家族氏名-1 | AG1: =IFERROR(__xludf.DUMMYFUNCTION("""COMPUTED_VALUE"""),"続柄-1") -> 続柄-1 | AH1: =IFERROR(__xludf.DUMMYFUNCTION("""COMPUTED_VALUE"""),"住所-1") -> 住所-1 | AI1: =IFERROR(__xludf.DUMMYFUNCTION("""COMPUTED_VALUE"""),"同居有無-1") -> 同居有無-1 | AJ1: =IFERROR(__xludf.DUMMYFUNCTION("""COMPUTED_VALUE"""),"介護-1") -> 介護-1 | AK1: =IFERROR(__xludf.DUMMYFUNCTION("""COMPUTED_VALUE"""),"就労-1") -> 就労-1 | AL1: =IFERROR(__xludf.DUMMYFUNCTION("""COMPUTED_VALUE"""),"連絡先-1") -> 連絡先-1 | AM1: =IFERROR(__xludf.DUMMYFUNCTION("""COMPUTED_VALUE"""),"備考-1") -> 備考-1 | AN1: =IFERROR(__xludf.DUMMYFUNCTION("""COMPUTED_VALUE"""),"家族氏名-2") -> 家族氏名-2 | AO1: =IFERROR(__xludf.DUMMYFUNCTION("""COMPUTED_VALUE"""),"続柄-2") -> 続柄-2 | AP1: =IFERROR(__xludf.DUMMYFUNCTION("""COMPUTED_VALUE"""),"住所-2") -> 住所-2 | AQ1: =IFERROR(__xludf.DUMMYFUNCTION("""COMPUTED_VALUE"""),"同居有無-2") -> 同居有無-2 | AR1: =IFERROR(__xludf.DUMMYFUNCTION("""COMPUTED_VALUE"""),"介護-2") -> 介護-2 | AS1: =IFERROR(__xludf.DUMMYFUNCTION("""COMPUTED_VALUE"""),"就労-2") -> 就労-2 | AT1: =IFERROR(__xludf.DUMMYFUNCTION("""COMPUTED_VALUE"""),"連絡先-2") -> 連絡先-2 | AU1: =IFERROR(__xludf.DUMMYFUNCTION("""COMPUTED_VALUE"""),"備考-2") -> 備考-2 | AV1: =IFERROR(__xludf.DUMMYFUNCTION("""COMPUTED_VALUE"""),"←｜家族状況") -> ←｜家族状況 | AW1: =IFERROR(__xludf.DUMMYFUNCTION("""COMPUTED_VALUE"""),"▶居住状況") -> ▶居住状況 | AX1: =IFERROR(__xludf.DUMMYFUNCTION("""COMPUTED_VALUE"""),"家庭環境") -> 家庭環境 | AY1: =IFERROR(__xludf.DUMMYFUNCTION("""COMPUTED_VALUE"""),"住宅形態") -> 住宅形態 | AZ1: =IFERROR(__xludf.DUMMYFUNCTION("""COMPUTED_VALUE"""),"住宅形態｜エレベーターの有無") -> 住宅形態｜エレベーターの有無 | BA1: =IFERROR(__xludf.DUMMYFUNCTION("""COMPUTED_VALUE"""),"住宅権利") -> 住宅権利 | BB1: =IFERROR(__xludf.DUMMYFUNCTION("""COMPUTED_VALUE"""),"専有居室") -> 専有居室 | BC1: =IFERROR(__xludf.DUMMYFUNCTION("""COMPUTED_VALUE"""),"冷暖房") -> 冷暖房 | BD1: =IFERROR(__xludf.DUMMYFUNCTION("""COMPUTED_VALUE"""),"トイレ") -> トイレ | BE1: =IFERROR(__xludf.DUMMYFUNCTION("""COMPUTED_VALUE"""),"手すりの有無") -> 手すりの有無 | BF1: =IFERROR(__xludf.DUMMYFUNCTION("""COMPUTED_VALUE"""),"段差の有無") -> 段差の有無 | BG1: =IFERROR(__xludf.DUMMYFUNCTION("""COMPUTED_VALUE"""),"浴室") -> 浴室 | BH1: =IFERROR(__xludf.DUMMYFUNCTION("""COMPUTED_VALUE"""),"浴室内手すり") -> 浴室内手すり | BI1: =IFERROR(__xludf.DUMMYFUNCTION("""COMPUTED_VALUE"""),"就寝") -> 就寝 | BJ1: =IFERROR(__xludf.DUMMYFUNCTION("""COMPUTED_VALUE"""),"居室段差") -> 居室段差 | BK1: =IFERROR(__xludf.DUMMYFUNCTION("""COMPUTED_VALUE"""),"住宅改修") -> 住宅改修 | BL1: =IFERROR(__xludf.DUMMYFUNCTION("""COMPUTED_VALUE"""),"住宅改修の必要性") -> 住宅改修の必要性 | BM1: =IFERROR(__xludf.DUMMYFUNCTION("""COMPUTED_VALUE"""),"特別な状況") -> 特別な状況 | BN1: =IFERROR(__xludf.DUMMYFUNCTION("""COMPUTED_VALUE"""),"←｜居住状況") -> ←｜居住状況 | BO1: =IFERROR(__xludf.DUMMYFUNCTION("""COMPUTED_VALUE"""),"▶利用サービス") -> ▶利用サービス | BP1: =IFERROR(__xludf.DUMMYFUNCTION("""COMPUTED_VALUE"""),"介護サービス") -> 介護サービス | BQ1: =IFERROR(__xludf.DUMMYFUNCTION("""COMPUTED_VALUE"""),"福祉用具") -> 福祉用具 | BR1: =IFERROR(__xludf.DUMMYFUNCTION("""COMPUTED_VALUE"""),"その他") -> その他 | BS1: =IFERROR(__xludf.DUMMYFUNCTION("""COMPUTED_VALUE"""),"インフォーマルサービス") -> インフォーマルサービス | BT1: =IFERROR(__xludf.DUMMYFUNCTION("""COMPUTED_VALUE"""),"社会との関り") -> 社会との関り | BU1: =IFERROR(__xludf.DUMMYFUNCTION("""COMPUTED_VALUE"""),"←｜利用サービス") -> ←｜利用サービス | BV1: =IFERROR(__xludf.DUMMYFUNCTION("""COMPUTED_VALUE"""),"身体の状況") -> 身体の状況 | BW1: =IFERROR(__xludf.DUMMYFUNCTION("""COMPUTED_VALUE"""),"▶健康状態") -> ▶健康状態 | BX1: =IFERROR(__xludf.DUMMYFUNCTION("""COMPUTED_VALUE"""),"疾患名-1") -> 疾患名-1 | BY1: =IFERROR(__xludf.DUMMYFUNCTION("""COMPUTED_VALUE"""),"発症日-1") -> 発症日-1 | BZ1: =IFERROR(__xludf.DUMMYFUNCTION("""COMPUTED_VALUE"""),"疾患名-2") -> 疾患名-2 | CA1: =IFERROR(__xludf.DUMMYFUNCTION("""COMPUTED_VALUE"""),"発症日-2") -> 発症日-2 | CB1: =IFERROR(__xludf.DUMMYFUNCTION("""COMPUTED_VALUE"""),"疾患名-3") -> 疾患名-3 | CC1: =IFERROR(__xludf.DUMMYFUNCTION("""COMPUTED_VALUE"""),"発症日-3") -> 発症日-3 | CD1: =IFERROR(__xludf.DUMMYFUNCTION("""COMPUTED_VALUE"""),"疾患名-4") -> 疾患名-4 | CE1: =IFERROR(__xludf.DUMMYFUNCTION("""COMPUTED_VALUE"""),"発症日-4") -> 発症日-4 | CF1: =IFERROR(__xludf.DUMMYFUNCTION("""COMPUTED_VALUE"""),"疾患名-5") -> 疾患名-5 | CG1: =IFERROR(__xludf.DUMMYFUNCTION("""COMPUTED_VALUE"""),"発症日-5") -> 発症日-5 | CH1: =IFERROR(__xludf.DUMMYFUNCTION("""COMPUTED_VALUE"""),"疾患名-6") -> 疾患名-6 | CI1: =IFERROR(__xludf.DUMMYFUNCTION("""COMPUTED_VALUE"""),"発症日-6") -> 発症日-6 | CJ1: =IFERROR(__xludf.DUMMYFUNCTION("""COMPUTED_VALUE"""),"通院") -> 通院 | CK1: =IFERROR(__xludf.DUMMYFUNCTION("""COMPUTED_VALUE"""),"主治医※安濃津ろまん入居後（中）｜病院・医院") -> 主治医※安濃津ろまん入居後（中）｜病院・医院 | CL1: =IFERROR(__xludf.DUMMYFUNCTION("""COMPUTED_VALUE"""),"主治医※安濃津ろまん入居後（中）｜氏名") -> 主治医※安濃津ろまん入居後（中）｜氏名 | CM1: =IFERROR(__xludf.DUMMYFUNCTION("""COMPUTED_VALUE"""),"往診医｜病院・医院") -> 往診医｜病院・医院 | CN1: =IFERROR(__xludf.DUMMYFUNCTION("""COMPUTED_VALUE"""),"往診医｜氏名") -> 往診医｜氏名 | CO1: =IFERROR(__xludf.DUMMYFUNCTION("""COMPUTED_VALUE"""),"かかりつけ医①") -> かかりつけ医① | CP1: =IFERROR(__xludf.DUMMYFUNCTION("""COMPUTED_VALUE"""),"かかりつけ医②") -> かかりつけ医② | CQ1: =IFERROR(__xludf.DUMMYFUNCTION("""COMPUTED_VALUE"""),"かかりつけ医③") -> かかりつけ医③ | CR1: =IFERROR(__xludf.DUMMYFUNCTION("""COMPUTED_VALUE"""),"かかりつけ医④") -> かかりつけ医④ | CS1: =IFERROR(__xludf.DUMMYFUNCTION("""COMPUTED_VALUE"""),"既往歴") -> 既往歴 | CT1: =IFERROR(__xludf.DUMMYFUNCTION("""COMPUTED_VALUE"""),"服薬") -> 服薬 | CU1: =IFERROR(__xludf.DUMMYFUNCTION("""COMPUTED_VALUE"""),"アレルギー｜有無") -> アレルギー｜有無 | CV1: =IFERROR(__xludf.DUMMYFUNCTION("""COMPUTED_VALUE"""),"アレルギー｜特記") -> アレルギー｜特記 | CW1: =IFERROR(__xludf.DUMMYFUNCTION("""COMPUTED_VALUE"""),"←｜健康状態") -> ←｜健康状態 | CX1: =IFERROR(__xludf.DUMMYFUNCTION("""COMPUTED_VALUE"""),"▶身体状況") -> ▶身体状況 | CY1: =IFERROR(__xludf.DUMMYFUNCTION("""COMPUTED_VALUE"""),"皮膚疾患") -> 皮膚疾患 | CZ1: =IFERROR(__xludf.DUMMYFUNCTION("""COMPUTED_VALUE"""),"感染症") -> 感染症 | DA1: =IFERROR(__xludf.DUMMYFUNCTION("""COMPUTED_VALUE"""),"特別な医療処置") -> 特別な医療処置 | DB1: =IFERROR(__xludf.DUMMYFUNCTION("""COMPUTED_VALUE"""),"麻痺") -> 麻痺 | DC1: =IFERROR(__xludf.DUMMYFUNCTION("""COMPUTED_VALUE"""),"痛み") -> 痛み | DD1: =IFERROR(__xludf.DUMMYFUNCTION("""COMPUTED_VALUE"""),"身長") -> 身長 | DE1: =IFERROR(__xludf.DUMMYFUNCTION("""COMPUTED_VALUE"""),"体重") -> 体重 | DF1: =IFERROR(__xludf.DUMMYFUNCTION("""COMPUTED_VALUE"""),"視力") -> 視力 | DG1: =IFERROR(__xludf.DUMMYFUNCTION("""COMPUTED_VALUE"""),"眼鏡等") -> 眼鏡等 | DH1: =IFERROR(__xludf.DUMMYFUNCTION("""COMPUTED_VALUE"""),"聴力") -> 聴力 | DI1: =IFERROR(__xludf.DUMMYFUNCTION("""COMPUTED_VALUE"""),"補聴器等") -> 補聴器等 | DJ1: =IFERROR(__xludf.DUMMYFUNCTION("""COMPUTED_VALUE"""),"身体状況｜特記事項") -> 身体状況｜特記事項 | DK1: =IFERROR(__xludf.DUMMYFUNCTION("""COMPUTED_VALUE"""),"←｜身体状況") -> ←｜身体状況 | DL1: =IFERROR(__xludf.DUMMYFUNCTION("""COMPUTED_VALUE"""),"▶認知機能") -> ▶認知機能 | DM1: =IFERROR(__xludf.DUMMYFUNCTION("""COMPUTED_VALUE"""),"認知症の有無") -> 認知症の有無 | DN1: =IFERROR(__xludf.DUMMYFUNCTION("""COMPUTED_VALUE"""),"認知症の程度") -> 認知症の程度 | DO1: =IFERROR(__xludf.DUMMYFUNCTION("""COMPUTED_VALUE"""),"BPSD") -> BPSD | DP1: =IFERROR(__xludf.DUMMYFUNCTION("""COMPUTED_VALUE"""),"会話") -> 会話 | DQ1: =IFERROR(__xludf.DUMMYFUNCTION("""COMPUTED_VALUE"""),"意思疎通") -> 意思疎通 | DR1: =IFERROR(__xludf.DUMMYFUNCTION("""COMPUTED_VALUE"""),"認知機能｜特記事項") -> 認知機能｜特記事項 | DS1: =IFERROR(__xludf.DUMMYFUNCTION("""COMPUTED_VALUE"""),"←｜認知機能") -> ←｜認知機能 | DT1: =IFERROR(__xludf.DUMMYFUNCTION("""COMPUTED_VALUE"""),"日常生活動作") -> 日常生活動作 | DU1: =IFERROR(__xludf.DUMMYFUNCTION("""COMPUTED_VALUE"""),"▶基本動作") -> ▶基本動作 | DV1: =IFERROR(__xludf.DUMMYFUNCTION("""COMPUTED_VALUE"""),"寝返り") -> 寝返り | DW1: =IFERROR(__xludf.DUMMYFUNCTION("""COMPUTED_VALUE"""),"起き上がり") -> 起き上がり | DX1: =IFERROR(__xludf.DUMMYFUNCTION("""COMPUTED_VALUE"""),"座位") -> 座位 | DY1: =IFERROR(__xludf.DUMMYFUNCTION("""COMPUTED_VALUE"""),"立ち上がり") -> 立ち上がり | DZ1: =IFERROR(__xludf.DUMMYFUNCTION("""COMPUTED_VALUE"""),"立位") -> 立位 | EA1: =IFERROR(__xludf.DUMMYFUNCTION("""COMPUTED_VALUE"""),"移乗") -> 移乗 | EB1: =IFERROR(__xludf.DUMMYFUNCTION("""COMPUTED_VALUE"""),"屋内移動") -> 屋内移動 | EC1: =IFERROR(__xludf.DUMMYFUNCTION("""COMPUTED_VALUE"""),"屋内移動｜使用用具") -> 屋内移動｜使用用具 | ED1: =IFERROR(__xludf.DUMMYFUNCTION("""COMPUTED_VALUE"""),"屋外移動") -> 屋外移動 | EE1: =IFERROR(__xludf.DUMMYFUNCTION("""COMPUTED_VALUE"""),"屋外移動｜使用用具") -> 屋外移動｜使用用具 | EF1: =IFERROR(__xludf.DUMMYFUNCTION("""COMPUTED_VALUE"""),"基本動作｜特記事項") -> 基本動作｜特記事項 | EG1: =IFERROR(__xludf.DUMMYFUNCTION("""COMPUTED_VALUE"""),"←｜基本動作") -> ←｜基本動作 | EH1: =IFERROR(__xludf.DUMMYFUNCTION("""COMPUTED_VALUE"""),"▶ADL") -> ▶ADL | EI1: =IFERROR(__xludf.DUMMYFUNCTION("""COMPUTED_VALUE"""),"＞食事") -> ＞食事 | EJ1: =IFERROR(__xludf.DUMMYFUNCTION("""COMPUTED_VALUE"""),"食事方法") -> 食事方法 | EK1: =IFERROR(__xludf.DUMMYFUNCTION("""COMPUTED_VALUE"""),"食事動作") -> 食事動作 | EL1: =IFERROR(__xludf.DUMMYFUNCTION("""COMPUTED_VALUE"""),"嚥下") -> 嚥下 | EM1: =IFERROR(__xludf.DUMMYFUNCTION("""COMPUTED_VALUE"""),"食事形態｜主食") -> 食事形態｜主食 | EN1: =IFERROR(__xludf.DUMMYFUNCTION("""COMPUTED_VALUE"""),"食事形態｜副食") -> 食事形態｜副食 | EO1: =IFERROR(__xludf.DUMMYFUNCTION("""COMPUTED_VALUE"""),"水分とろみ") -> 水分とろみ | EP1: =IFERROR(__xludf.DUMMYFUNCTION("""COMPUTED_VALUE"""),"食事制限") -> 食事制限 | EQ1: =IFERROR(__xludf.DUMMYFUNCTION("""COMPUTED_VALUE"""),"道具・用具") -> 道具・用具 | ER1: =IFERROR(__xludf.DUMMYFUNCTION("""COMPUTED_VALUE"""),"食事｜特記事項") -> 食事｜特記事項 | ES1: =IFERROR(__xludf.DUMMYFUNCTION("""COMPUTED_VALUE"""),"←｜食事") -> ←｜食事 | ET1: =IFERROR(__xludf.DUMMYFUNCTION("""COMPUTED_VALUE"""),"＞口腔") -> ＞口腔 | EU1: =IFERROR(__xludf.DUMMYFUNCTION("""COMPUTED_VALUE"""),"口腔衛生") -> 口腔衛生 | EV1: =IFERROR(__xludf.DUMMYFUNCTION("""COMPUTED_VALUE"""),"自歯の有無") -> 自歯の有無 | EW1: =IFERROR(__xludf.DUMMYFUNCTION("""COMPUTED_VALUE"""),"義歯の有無") -> 義歯の有無 | EX1: =IFERROR(__xludf.DUMMYFUNCTION("""COMPUTED_VALUE"""),"義歯の種類") -> 義歯の種類 | EY1: =IFERROR(__xludf.DUMMYFUNCTION("""COMPUTED_VALUE"""),"義歯の場所") -> 義歯の場所 | EZ1: =IFERROR(__xludf.DUMMYFUNCTION("""COMPUTED_VALUE"""),"口腔｜特記事項") -> 口腔｜特記事項 | FA1: =IFERROR(__xludf.DUMMYFUNCTION("""COMPUTED_VALUE"""),"←｜口腔") -> ←｜口腔 | FB1: =IFERROR(__xludf.DUMMYFUNCTION("""COMPUTED_VALUE"""),"＞入浴・更衣") -> ＞入浴・更衣 | FC1: =IFERROR(__xludf.DUMMYFUNCTION("""COMPUTED_VALUE"""),"入浴動作") -> 入浴動作 | FD1: =IFERROR(__xludf.DUMMYFUNCTION("""COMPUTED_VALUE"""),"形態") -> 形態 | FE1: =IFERROR(__xludf.DUMMYFUNCTION("""COMPUTED_VALUE"""),"入浴の制限") -> 入浴の制限 | FF1: =IFERROR(__xludf.DUMMYFUNCTION("""COMPUTED_VALUE"""),"←｜入浴") -> ←｜入浴 | FG1: =IFERROR(__xludf.DUMMYFUNCTION("""COMPUTED_VALUE"""),"上衣") -> 上衣 | FH1: =IFERROR(__xludf.DUMMYFUNCTION("""COMPUTED_VALUE"""),"下衣") -> 下衣 | FI1: =IFERROR(__xludf.DUMMYFUNCTION("""COMPUTED_VALUE"""),"入浴・更衣｜特記事項") -> 入浴・更衣｜特記事項 | FJ1: =IFERROR(__xludf.DUMMYFUNCTION("""COMPUTED_VALUE"""),"←｜更衣") -> ←｜更衣 | FK1: =IFERROR(__xludf.DUMMYFUNCTION("""COMPUTED_VALUE"""),"＞排泄") -> ＞排泄 | FL1: =IFERROR(__xludf.DUMMYFUNCTION("""COMPUTED_VALUE"""),"排泄動作") -> 排泄動作 | FM1: =IFERROR(__xludf.DUMMYFUNCTION("""COMPUTED_VALUE"""),"尿意") -> 尿意 | FN1: =IFERROR(__xludf.DUMMYFUNCTION("""COMPUTED_VALUE"""),"尿失禁") -> 尿失禁 | FO1: =IFERROR(__xludf.DUMMYFUNCTION("""COMPUTED_VALUE"""),"便意") -> 便意 | FP1: =IFERROR(__xludf.DUMMYFUNCTION("""COMPUTED_VALUE"""),"便失禁") -> 便失禁 | FQ1: =IFERROR(__xludf.DUMMYFUNCTION("""COMPUTED_VALUE"""),"状況") -> 状況 | FR1: =IFERROR(__xludf.DUMMYFUNCTION("""COMPUTED_VALUE"""),"場所｜日中") -> 場所｜日中 | FS1: =IFERROR(__xludf.DUMMYFUNCTION("""COMPUTED_VALUE"""),"場所｜夜間") -> 場所｜夜間 | FT1: =IFERROR(__xludf.DUMMYFUNCTION("""COMPUTED_VALUE"""),"排泄用品") -> 排泄用品 | FU1: =IFERROR(__xludf.DUMMYFUNCTION("""COMPUTED_VALUE"""),"排泄｜特記事項") -> 排泄｜特記事項 | FV1: =IFERROR(__xludf.DUMMYFUNCTION("""COMPUTED_VALUE"""),"←｜排泄") -> ←｜排泄 | FW1: =IFERROR(__xludf.DUMMYFUNCTION("""COMPUTED_VALUE"""),"←｜ADL") -> ←｜ADL | FX1: =IFERROR(__xludf.DUMMYFUNCTION("""COMPUTED_VALUE"""),"▶IADL") -> ▶IADL | FY1: =IFERROR(__xludf.DUMMYFUNCTION("""COMPUTED_VALUE"""),"調理") -> 調理 | FZ1: =IFERROR(__xludf.DUMMYFUNCTION("""COMPUTED_VALUE"""),"掃除") -> 掃除 | GA1: =IFERROR(__xludf.DUMMYFUNCTION("""COMPUTED_VALUE"""),"洗濯") -> 洗濯 | GB1: =IFERROR(__xludf.DUMMYFUNCTION("""COMPUTED_VALUE"""),"買い物") -> 買い物 | GC1: =IFERROR(__xludf.DUMMYFUNCTION("""COMPUTED_VALUE"""),"金銭管理") -> 金銭管理 | GD1: =IFERROR(__xludf.DUMMYFUNCTION("""COMPUTED_VALUE"""),"IADL｜特記事項") -> IADL｜特記事項 | GE1: =IFERROR(__xludf.DUMMYFUNCTION("""COMPUTED_VALUE"""),"←｜IADL") -> ←｜IADL | GF1: =IFERROR(__xludf.DUMMYFUNCTION("""COMPUTED_VALUE"""),"特記・備考") -> 特記・備考 | GG1: =IFERROR(__xludf.DUMMYFUNCTION("""COMPUTED_VALUE"""),"その他、特記事項") -> その他、特記事項 | GH1: =IFERROR(__xludf.DUMMYFUNCTION("""COMPUTED_VALUE"""),"所要時間") -> 所要時間 | GI1: =IFERROR(__xludf.DUMMYFUNCTION("""COMPUTED_VALUE"""),"")
C2: =IFERROR(__xludf.DUMMYFUNCTION("""COMPUTED_VALUE"""),"藤村 國造") -> 藤村 國造 | D2: =IFERROR(__xludf.DUMMYFUNCTION("""COMPUTED_VALUE"""),"1231") -> 1231 | I2: =IFERROR(__xludf.DUMMYFUNCTION("""COMPUTED_VALUE"""),45477) -> 45477 | J2: =IFERROR(__xludf.DUMMYFUNCTION("""COMPUTED_VALUE"""),"山川 和輝") -> 山川 和輝 | K2: =IFERROR(__xludf.DUMMYFUNCTION("""COMPUTED_VALUE"""),"新規") -> 新規 | L2: =IFERROR(__xludf.DUMMYFUNCTION("""COMPUTED_VALUE"""),"入院先の病院") -> 入院先の病院 | M2: =IFERROR(__xludf.DUMMYFUNCTION("""COMPUTED_VALUE"""),"自宅で夫婦2人暮らし。2年ほど前から尿汚染が多くなり妻の介護も限界となってきたため、有料老人ホームに入所となったが、入所から2～3ヶ月経つ頃、熱発を度々繰り返すようになり、三重中央医療センターに入院となる。何かしらの原因で腰椎からの細菌感染によるもので抗生剤治療を行う。その後、榊原温泉病院に転院して治療を継続。榊原温泉病院での入院期間は約1年程度あったが、状態が落ち着いてきたこともあり、自宅で生活することは困難なため安濃津ろまんへ入居の申し込みをされた。") -> 自宅で夫婦2人暮らし。2年ほど前から尿汚染が多くなり妻の介護も限界となってきたため、有料老人ホームに入所となったが、入所から2～3ヶ月経つ頃、熱発を度々繰り返すようになり、三重中央医療センターに入院となる。何かしらの原因で腰椎からの細菌感染によるもので抗生剤治療を行う。その後、榊原温泉病院に転院して治療を継続。榊原温泉病院での入院期間は約1年程度あったが、状態が落ち着いてきたこともあり、自宅で生活することは困難なため安濃津ろまんへ入居の申し込みをされた。 | N2: =IFERROR(__xludf.DUMMYFUNCTION("""COMPUTED_VALUE"""),"眠られており意向の聴取が困難でだった。") -> 眠られており意向の聴取が困難でだった。 | Q2: =IFERROR(__xludf.DUMMYFUNCTION("""COMPUTED_VALUE"""),"入力") -> 入力 | R2: =IFERROR(__xludf.DUMMYFUNCTION("""COMPUTED_VALUE"""),"要介護５") -> 要介護５ | AE2: =IFERROR(__xludf.DUMMYFUNCTION("""COMPUTED_VALUE"""),"入力") -> 入力 | AF2: =IFERROR(__xludf.DUMMYFUNCTION("""COMPUTED_VALUE"""),"藤村 高行") -> 藤村 高行 | AG2: =IFERROR(__xludf.DUMMYFUNCTION("""COMPUTED_VALUE"""),"長男") -> 長男 | AI2: =IFERROR(__xludf.DUMMYFUNCTION("""COMPUTED_VALUE"""),"別居") -> 別居 | AJ2: =IFERROR(__xludf.DUMMYFUNCTION("""COMPUTED_VALUE"""),"介護する") -> 介護する | AK2: =IFERROR(__xludf.DUMMYFUNCTION("""COMPUTED_VALUE"""),"有") -> 有 | AL2: =IFERROR(__xludf.DUMMYFUNCTION("""COMPUTED_VALUE"""),"090-7693-3788") -> 090-7693-3788 | AM2: =IFERROR(__xludf.DUMMYFUNCTION("""COMPUTED_VALUE"""),"KP。津市河芸町在住。") -> KP。津市河芸町在住。 | AN2: =IFERROR(__xludf.DUMMYFUNCTION("""COMPUTED_VALUE"""),"藤村 聡美") -> 藤村 聡美 | AO2: =IFERROR(__xludf.DUMMYFUNCTION("""COMPUTED_VALUE"""),"長男の妻") -> 長男の妻 | AQ2: =IFERROR(__xludf.DUMMYFUNCTION("""COMPUTED_VALUE"""),"別居") -> 別居 | AT2: =IFERROR(__xludf.DUMMYFUNCTION("""COMPUTED_VALUE"""),"090-5457-1470") -> 090-5457-1470 | AU2: =IFERROR(__xludf.DUMMYFUNCTION("""COMPUTED_VALUE"""),"介護、就労状況は不明。") -> 介護、就労状況は不明。 | AW2: =IFERROR(__xludf.DUMMYFUNCTION("""COMPUTED_VALUE"""),"入力") -> 入力 | AX2: =IFERROR(__xludf.DUMMYFUNCTION("""COMPUTED_VALUE"""),"一人暮らし") -> 一人暮らし | AY2: =IFERROR(__xludf.DUMMYFUNCTION("""COMPUTED_VALUE"""),"集合住宅") -> 集合住宅 | AZ2: =IFERROR(__xludf.DUMMYFUNCTION("""COMPUTED_VALUE"""),"エレベーター有") -> エレベーター有 | BA2: =IFERROR(__xludf.DUMMYFUNCTION("""COMPUTED_VALUE"""),"賃貸") -> 賃貸 | BB2: =IFERROR(__xludf.DUMMYFUNCTION("""COMPUTED_VALUE"""),"有") -> 有 | BC2: =IFERROR(__xludf.DUMMYFUNCTION("""COMPUTED_VALUE"""),"有") -> 有 | BD2: =IFERROR(__xludf.DUMMYFUNCTION("""COMPUTED_VALUE"""),"ウォシュレット") -> ウォシュレット | BG2: =IFERROR(__xludf.DUMMYFUNCTION("""COMPUTED_VALUE"""),"無") -> 無 | BI2: =IFERROR(__xludf.DUMMYFUNCTION("""COMPUTED_VALUE"""),"リクライニングベッド") -> リクライニングベッド | BJ2: =IFERROR(__xludf.DUMMYFUNCTION("""COMPUTED_VALUE"""),"無") -> 無 | BK2: =IFERROR(__xludf.DUMMYFUNCTION("""COMPUTED_VALUE"""),"無") -> 無 | BL2: =IFERROR(__xludf.DUMMYFUNCTION("""COMPUTED_VALUE"""),"無") -> 無 | BW2: =IFERROR(__xludf.DUMMYFUNCTION("""COMPUTED_VALUE"""),"入力") -> 入力 | BX2: =IFERROR(__xludf.DUMMYFUNCTION("""COMPUTED_VALUE"""),"MRSA感染性心内膜炎") -> MRSA感染性心内膜炎 | BY2: =IFERROR(__xludf.DUMMYFUNCTION("""COMPUTED_VALUE"""),"2022/12/16") -> 2022/12/16 | BZ2: =IFERROR(__xludf.DUMMYFUNCTION("""COMPUTED_VALUE"""),"COVID19感染") -> COVID19感染 | CA2: =IFERROR(__xludf.DUMMYFUNCTION("""COMPUTED_VALUE"""),"2023/01/26") -> 2023/01/26 | CB2: =IFERROR(__xludf.DUMMYFUNCTION("""COMPUTED_VALUE"""),"誤嚥性肺炎") -> 誤嚥性肺炎 | CC2: =IFERROR(__xludf.DUMMYFUNCTION("""COMPUTED_VALUE"""),"2023/02/07") -> 2023/02/07 | CD2: =IFERROR(__xludf.DUMMYFUNCTION("""COMPUTED_VALUE"""),"神経因性膀胱") -> 神経因性膀胱 | CE2: =IFERROR(__xludf.DUMMYFUNCTION("""COMPUTED_VALUE"""),"2023/08/12") -> 2023/08/12 | CF2: =IFERROR(__xludf.DUMMYFUNCTION("""COMPUTED_VALUE"""),"化膿性脊髄炎") -> 化膿性脊髄炎 | CG2: =IFERROR(__xludf.DUMMYFUNCTION("""COMPUTED_VALUE"""),"2023/08/12") -> 2023/08/12 | CJ2: =IFERROR(__xludf.DUMMYFUNCTION("""COMPUTED_VALUE"""),"現在入院中。 退院後、化膿性脊髄炎による発熱が予見され、発熱された場合は整形外科を受診。（武内病院へ受診予定） バルーンカテーテルを使用されており、武内病院で月1回の頻度で交換が必要。") -> 現在入院中。 退院後、化膿性脊髄炎による発熱が予見され、発熱された場合は整形外科を受診。（武内病院へ受診予定） バルーンカテーテルを使用されており、武内病院で月1回の頻度で交換が必要。 | CT2: =IFERROR(__xludf.DUMMYFUNCTION("""COMPUTED_VALUE"""),"［薬情報］ カロナール錠200 トラゼンタ錠5ｍｇ カンデサルタンOD錠8ｍｇ ミノサイクリン塩酸塩カプセル100ｍｇ アゾセミド錠30ｍｇ") -> ［薬情報］ カロナール錠200 トラゼンタ錠5ｍｇ カンデサルタンOD錠8ｍｇ ミノサイクリン塩酸塩カプセル100ｍｇ アゾセミド錠30ｍｇ | CX2: =IFERROR(__xludf.DUMMYFUNCTION("""COMPUTED_VALUE"""),"入力") -> 入力 | CY2: =IFERROR(__xludf.DUMMYFUNCTION("""COMPUTED_VALUE"""),"無") -> 無 | CZ2: =IFERROR(__xludf.DUMMYFUNCTION("""COMPUTED_VALUE"""),"無") -> 無 | DA2: =IFERROR(__xludf.DUMMYFUNCTION("""COMPUTED_VALUE"""),"カテーテル") -> カテーテル | DB2: =IFERROR(__xludf.DUMMYFUNCTION("""COMPUTED_VALUE"""),"なし") -> なし | DC2: =IFERROR(__xludf.DUMMYFUNCTION("""COMPUTED_VALUE"""),"左股関節に拘縮があり他動で痛みあり。") -> 左股関節に拘縮があり他動で痛みあり。 | DD2: =IFERROR(__xludf.DUMMYFUNCTION("""COMPUTED_VALUE"""),149) -> 149 | DE2: =IFERROR(__xludf.DUMMYFUNCTION("""COMPUTED_VALUE"""),42) -> 42 | DF2: =IFERROR(__xludf.DUMMYFUNCTION("""COMPUTED_VALUE"""),"大きい字は可") -> 大きい字は可 | DG2: =IFERROR(__xludf.DUMMYFUNCTION("""COMPUTED_VALUE"""),"有") -> 有 | DH2: =IFERROR(__xludf.DUMMYFUNCTION("""COMPUTED_VALUE"""),"大きい声は可") -> 大きい声は可 | DI2: =IFERROR(__xludf.DUMMYFUNCTION("""COMPUTED_VALUE"""),"無") -> 無 | DJ2: =IFERROR(__xludf.DUMMYFUNCTION("""COMPUTED_VALUE"""),"MRSAの既往があるものの、現在は特に問題なし。 左股関節に拘縮があり、他動で動かすことで痛みを生じる。 難聴があり、大きな声で話す必要があるが、声が大きすぎると時折「うるさい。」と言われることもある。 インシュリンは必要ないが、現在は血糖測定を月木の朝昼晩で行っているが、退院時はなしになる予定。") -> MRSAの既往があるものの、現在は特に問題なし。 左股関節に拘縮があり、他動で動かすことで痛みを生じる。 難聴があり、大きな声で話す必要があるが、声が大きすぎると時折「うるさい。」と言われることもある。 インシュリンは必要ないが、現在は血糖測定を月木の朝昼晩で行っているが、退院時はなしになる予定。 | DL2: =IFERROR(__xludf.DUMMYFUNCTION("""COMPUTED_VALUE"""),"入力") -> 入力 | DM2: =IFERROR(__xludf.DUMMYFUNCTION("""COMPUTED_VALUE"""),"有") -> 有 | DO2: =IFERROR(__xludf.DUMMYFUNCTION("""COMPUTED_VALUE"""),"無") -> 無 | DP2: =IFERROR(__xludf.DUMMYFUNCTION("""COMPUTED_VALUE"""),"不明瞭") -> 不明瞭 | DQ2: =IFERROR(__xludf.DUMMYFUNCTION("""COMPUTED_VALUE"""),"その場のみ可") -> その場のみ可 | DR2: =IFERROR(__xludf.DUMMYFUNCTION("""COMPUTED_VALUE"""),"認知機能の低下はあるものの、精査が困難。問題行動や介護抵抗等は見られない。") -> 認知機能の低下はあるものの、精査が困難。問題行動や介護抵抗等は見られない。 | DU2: =IFERROR(__xludf.DUMMYFUNCTION("""COMPUTED_VALUE"""),"入力") -> 入力 | DV2: =IFERROR(__xludf.DUMMYFUNCTION("""COMPUTED_VALUE"""),"できない") -> できない | DW2: =IFERROR(__xludf.DUMMYFUNCTION("""COMPUTED_VALUE"""),"できない") -> できない | DX2: =IFERROR(__xludf.DUMMYFUNCTION("""COMPUTED_VALUE"""),"支えてもらえればできる") -> 支えてもらえればできる | DY2: =IFERROR(__xludf.DUMMYFUNCTION("""COMPUTED_VALUE"""),"できない") -> できない | DZ2: =IFERROR(__xludf.DUMMYFUNCTION("""COMPUTED_VALUE"""),"できない") -> できない | EA2: =IFERROR(__xludf.DUMMYFUNCTION("""COMPUTED_VALUE"""),"全介助") -> 全介助 | EB2: =IFERROR(__xludf.DUMMYFUNCTION("""COMPUTED_VALUE"""),"全介助") -> 全介助 | EC2: =IFERROR(__xludf.DUMMYFUNCTION("""COMPUTED_VALUE"""),"車椅子") -> 車椅子 | ED2: =IFERROR(__xludf.DUMMYFUNCTION("""COMPUTED_VALUE"""),"全介助") -> 全介助 | EE2: =IFERROR(__xludf.DUMMYFUNCTION("""COMPUTED_VALUE"""),"車椅子") -> 車椅子 | EF2: =IFERROR(__xludf.DUMMYFUNCTION("""COMPUTED_VALUE"""),"移動はリクライニング車椅子が必要。リクライニング車椅子に座れば1～ 2時間程度は座り続けることができる。 基本動作は全介助となっている。 寝返りが自身で行うことができず、3～4時間に一度体位交換を行う必要がある。") -> 移動はリクライニング車椅子が必要。リクライニング車椅子に座れば1～ 2時間程度は座り続けることができる。 基本動作は全介助となっている。 寝返りが自身で行うことができず、3～4時間に一度体位交換を行う必要がある。 | EH2: =IFERROR(__xludf.DUMMYFUNCTION("""COMPUTED_VALUE"""),"入力") -> 入力 | EI2: =IFERROR(__xludf.DUMMYFUNCTION("""COMPUTED_VALUE"""),"入力") -> 入力 | EJ2: =IFERROR(__xludf.DUMMYFUNCTION("""COMPUTED_VALUE"""),"経口摂取") -> 経口摂取 | EK2: =IFERROR(__xludf.DUMMYFUNCTION("""COMPUTED_VALUE"""),"一部介助") -> 一部介助 | EL2: =IFERROR(__xludf.DUMMYFUNCTION("""COMPUTED_VALUE"""),"見守り等が必要") -> 見守り等が必要 | EM2: =IFERROR(__xludf.DUMMYFUNCTION("""COMPUTED_VALUE"""),"全粥") -> 全粥 | EN2: =IFERROR(__xludf.DUMMYFUNCTION("""COMPUTED_VALUE"""),"ペースト") -> ペースト | EO2: =IFERROR(__xludf.DUMMYFUNCTION("""COMPUTED_VALUE"""),"有") -> 有 | EP2: =IFERROR(__xludf.DUMMYFUNCTION("""COMPUTED_VALUE"""),"有") -> 有 | EQ2: =IFERROR(__xludf.DUMMYFUNCTION("""COMPUTED_VALUE"""),"スプーン , エプロン") -> スプーン , エプロン | ER2: =IFERROR(__xludf.DUMMYFUNCTION("""COMPUTED_VALUE"""),"食事はベッド上ギャッジアップ座位で自己摂取可能。しかし疲労により手が止まるため、その後は介助を行っている。食事中、姿勢が崩れることはないが、食事の支援が必要。食事摂取量は介助すれば8割程度は摂取可能。栄養補助食品のメイバランスと、朝にヨーグルトを食べている。 塩分制限食を食べられており、アレルギーはない。") -> 食事はベッド上ギャッジアップ座位で自己摂取可能。しかし疲労により手が止まるため、その後は介助を行っている。食事中、姿勢が崩れることはないが、食事の支援が必要。食事摂取量は介助すれば8割程度は摂取可能。栄養補助食品のメイバランスと、朝にヨーグルトを食べている。 塩分制限食を食べられており、アレルギーはない。 | ET2: =IFERROR(__xludf.DUMMYFUNCTION("""COMPUTED_VALUE"""),"入力") -> 入力 | EU2: =IFERROR(__xludf.DUMMYFUNCTION("""COMPUTED_VALUE"""),"全介助") -> 全介助 | EW2: =IFERROR(__xludf.DUMMYFUNCTION("""COMPUTED_VALUE"""),"無") -> 無 | EZ2: =IFERROR(__xludf.DUMMYFUNCTION("""COMPUTED_VALUE"""),"歯はすべてないものの、義歯は使用されていない。口腔ケアは口腔スポンジでふき取りを介助している。") -> 歯はすべてないものの、義歯は使用されていない。口腔ケアは口腔スポンジでふき取りを介助している。 | FB2: =IFERROR(__xludf.DUMMYFUNCTION("""COMPUTED_VALUE"""),"入力") -> 入力 | FC2: =IFERROR(__xludf.DUMMYFUNCTION("""COMPUTED_VALUE"""),"全介助") -> 全介助 | FD2: =IFERROR(__xludf.DUMMYFUNCTION("""COMPUTED_VALUE"""),"寝台浴") -> 寝台浴 | FE2: =IFERROR(__xludf.DUMMYFUNCTION("""COMPUTED_VALUE"""),"無") -> 無 | FG2: =IFERROR(__xludf.DUMMYFUNCTION("""COMPUTED_VALUE"""),"全介助") -> 全介助 | FH2: =IFERROR(__xludf.DUMMYFUNCTION("""COMPUTED_VALUE"""),"全介助") -> 全介助 | FI2: =IFERROR(__xludf.DUMMYFUNCTION("""COMPUTED_VALUE"""),"入浴、更衣は全介助となっている。") -> 入浴、更衣は全介助となっている。 | FK2: =IFERROR(__xludf.DUMMYFUNCTION("""COMPUTED_VALUE"""),"入力") -> 入力 | FL2: =IFERROR(__xludf.DUMMYFUNCTION("""COMPUTED_VALUE"""),"全介助") -> 全介助 | FM2: =IFERROR(__xludf.DUMMYFUNCTION("""COMPUTED_VALUE"""),"無") -> 無 | FN2: =IFERROR(__xludf.DUMMYFUNCTION("""COMPUTED_VALUE"""),"無") -> 無 | FO2: =IFERROR(__xludf.DUMMYFUNCTION("""COMPUTED_VALUE"""),"無") -> 無 | FP2: =IFERROR(__xludf.DUMMYFUNCTION("""COMPUTED_VALUE"""),"無") -> 無 | FR2: =IFERROR(__xludf.DUMMYFUNCTION("""COMPUTED_VALUE"""),"オムツ , カテーテル") -> オムツ , カテーテル | FS2: =IFERROR(__xludf.DUMMYFUNCTION("""COMPUTED_VALUE"""),"オムツ , カテーテル") -> オムツ , カテーテル | FT2: =IFERROR(__xludf.DUMMYFUNCTION("""COMPUTED_VALUE"""),"紙おむつ , 大パット") -> 紙おむつ , 大パット | FU2: =IFERROR(__xludf.DUMMYFUNCTION("""COMPUTED_VALUE"""),"排尿はバルーンカテーテルを使用している。 排便はオムツ内に行うため、オムツ交換が必要。") -> 排尿はバルーンカテーテルを使用している。 排便はオムツ内に行うため、オムツ交換が必要。 | FX2: =IFERROR(__xludf.DUMMYFUNCTION("""COMPUTED_VALUE"""),"入力") -> 入力 | FY2: =IFERROR(__xludf.DUMMYFUNCTION("""COMPUTED_VALUE"""),"全介助") -> 全介助 | FZ2: =IFERROR(__xludf.DUMMYFUNCTION("""COMPUTED_VALUE"""),"全介助") -> 全介助 | GA2: =IFERROR(__xludf.DUMMYFUNCTION("""COMPUTED_VALUE"""),"全介助") -> 全介助 | GB2: =IFERROR(__xludf.DUMMYFUNCTION("""COMPUTED_VALUE"""),"全介助") -> 全介助 | GC2: =IFERROR(__xludf.DUMMYFUNCTION("""COMPUTED_VALUE"""),"全介助") -> 全介助 | GD2: =IFERROR(__xludf.DUMMYFUNCTION("""COMPUTED_VALUE"""),"すべて介助が必要。") -> すべて介助が必要。 | GG2: =IFERROR(__xludf.DUMMYFUNCTION("""COMPUTED_VALUE"""),"【榊原温泉病院に入院前から現在までの経過】 元々要介護3で施設に入所していた。 2022年12月16日に発熱があり、三重中央医療センターへ救急搬送。MRSA感染性心内膜炎で抗生剤加療。その後2023年1月26日にCOVID19に感染、低ナトリウム血症等併発したが、2月6日に退院。しかし、翌日2月7日に再度発熱があり三重中央医療センターへ救急搬送。COVID19再感染疑いで再入院。誤嚥性肺炎併発あり抗生剤等で加療。2月18日～再度発熱あり、MRSA菌血症再燃、胆石胆嚢炎疑いで、絶食・抗生剤加療。その後食事再"&"開し介助で摂取可能も低アルブミン血症を認め、また入院の長期化に伴い廃用症候群と発熱を繰り返しており退院は困難な状況。継続加療・療養目的にて2023年4月4日に榊原温泉病院に転院。 6月24日血培やMRSA菌血症が判明しVCM投与で治療し一旦は落ち着いたが、腰痛が持続し8月5日から発熱あり、両側股関節痛や、胸腰椎移行部叩打痛あり、CPR24台で、CTの結果L5椎体内に多房性の低吸収域があり、化膿性脊髄炎や椎体腫瘍の可能性を指摘され8月12日に武内病院へ転院となる。精査の結果、ドレナージ適応無、手術も不可と判"&"断。全身浮腫、低栄養、胸水ありBa挿入8月14日Hb低下あり輸血施行。抗生剤投与での治療継続。8月17日に榊原温泉病院へ戻られた。 榊原温泉病院に戻られた後から現在にかけて状態は落ち着いている。") -> 【榊原温泉病院に入院前から現在までの経過】 元々要介護3で施設に入所していた。 2022年12月16日に発熱があり、三重中央医療センターへ救急搬送。MRSA感染性心内膜炎で抗生剤加療。その後2023年1月26日にCOVID19に感染、低ナトリウム血症等併発したが、2月6日に退院。しかし、翌日2月7日に再度発熱があり三重中央医療センターへ救急搬送。COVID19再感染疑いで再入院。誤嚥性肺炎併発あり抗生剤等で加療。2月18日～再度発熱あり、MRSA菌血症再燃、胆石胆嚢炎疑いで、絶食・抗生剤加療。その後食事再開し介助で摂取可能も低アルブミン血症を認め、また入院の長期化に伴い廃用症候群と発熱を繰り返しており退院は困難な状況。継続加療・療養目的にて2023年4月4日に榊原温泉病院に転院。 6月24日血培やMRSA菌血症が判明しVCM投与で治療し一旦は落ち着いたが、腰痛が持続し8月5日から発熱あり、両側股関節痛や、胸腰椎移行部叩打痛あり、CPR24台で、CTの結果L5椎体内に多房性の低吸収域があり、化膿性脊髄炎や椎体腫瘍の可能性を指摘され8月12日に武内病院へ転院となる。精査の結果、ドレナージ適応無、手術も不可と判断。全身浮腫、低栄養、胸水ありBa挿入8月14日Hb低下あり輸血施行。抗生剤投与での治療継続。8月17日に榊原温泉病院へ戻られた。 榊原温泉病院に戻られた後から現在にかけて状態は落ち着いている。 | GH2: =IFERROR(__xludf.DUMMYFUNCTION("""COMPUTED_VALUE"""),40) -> 40
C3: =IFERROR(__xludf.DUMMYFUNCTION("""COMPUTED_VALUE"""),"山岡 義夫") -> 山岡 義夫 | D3: =IFERROR(__xludf.DUMMYFUNCTION("""COMPUTED_VALUE"""),"98cbe691") -> 98cbe691 | E3: =IFERROR(__xludf.DUMMYFUNCTION("""COMPUTED_VALUE"""),"山川 和輝") -> 山川 和輝 | F3: =IFERROR(__xludf.DUMMYFUNCTION("""COMPUTED_VALUE"""),"や") -> や | G3: =IFERROR(__xludf.DUMMYFUNCTION("""COMPUTED_VALUE"""),"利用者選択｜絞り込み") -> 利用者選択｜絞り込み | I3: =IFERROR(__xludf.DUMMYFUNCTION("""COMPUTED_VALUE"""),45569) -> 45569 | J3: =IFERROR(__xludf.DUMMYFUNCTION("""COMPUTED_VALUE"""),"山川 和輝") -> 山川 和輝 | K3: =IFERROR(__xludf.DUMMYFUNCTION("""COMPUTED_VALUE"""),"新規") -> 新規 | L3: =IFERROR(__xludf.DUMMYFUNCTION("""COMPUTED_VALUE"""),"本人の居室") -> 本人の居室 | M3: =IFERROR(__xludf.DUMMYFUNCTION("""COMPUTED_VALUE"""),"自宅で自立生活を送り仕事にも通っていたが、令和5年11月に脳リンパ腫により三重大学病院に入院。令和6年5月末に退院し、3日間だけ自宅に戻ったが、歩行能力の低下と認知症が見られたため、リハビリ目的にて津生協病院に入院。約1ヶ月入院したところで、肺炎となり再び三重大学病院に入院。主治医より在宅復帰は困難と判断され、令和6年7月20日に安濃津ろまんへ入居となった。") -> 自宅で自立生活を送り仕事にも通っていたが、令和5年11月に脳リンパ腫により三重大学病院に入院。令和6年5月末に退院し、3日間だけ自宅に戻ったが、歩行能力の低下と認知症が見られたため、リハビリ目的にて津生協病院に入院。約1ヶ月入院したところで、肺炎となり再び三重大学病院に入院。主治医より在宅復帰は困難と判断され、令和6年7月20日に安濃津ろまんへ入居となった。 | O3: =IFERROR(__xludf.DUMMYFUNCTION("""COMPUTED_VALUE"""),"もう家で介護はできないので、施設でリハビリを受けて前のように楽に動けるようになってほしいと思っています。") -> もう家で介護はできないので、施設でリハビリを受けて前のように楽に動けるようになってほしいと思っています。 | Q3: =IFERROR(__xludf.DUMMYFUNCTION("""COMPUTED_VALUE"""),"入力") -> 入力 | R3: =IFERROR(__xludf.DUMMYFUNCTION("""COMPUTED_VALUE"""),"要介護３") -> 要介護３ | S3: =IFERROR(__xludf.DUMMYFUNCTION("""COMPUTED_VALUE"""),"令和6年9月3日") -> 令和6年9月3日 | T3: =IFERROR(__xludf.DUMMYFUNCTION("""COMPUTED_VALUE"""),"令和6年8月1日") -> 令和6年8月1日 | U3: =IFERROR(__xludf.DUMMYFUNCTION("""COMPUTED_VALUE"""),"令和7年7月31日") -> 令和7年7月31日 | V3: =IFERROR(__xludf.DUMMYFUNCTION("""COMPUTED_VALUE"""),"１割負担") -> １割負担 | W3: =IFERROR(__xludf.DUMMYFUNCTION("""COMPUTED_VALUE"""),"国民健康保険") -> 国民健康保険 | X3: =IFERROR(__xludf.DUMMYFUNCTION("""COMPUTED_VALUE"""),"無") -> 無 | Z3: =IFERROR(__xludf.DUMMYFUNCTION("""COMPUTED_VALUE"""),"無") -> 無 | AA3: =IFERROR(__xludf.DUMMYFUNCTION("""COMPUTED_VALUE"""),"無") -> 無 | AE3: =IFERROR(__xludf.DUMMYFUNCTION("""COMPUTED_VALUE"""),"入力") -> 入力 | AF3: =IFERROR(__xludf.DUMMYFUNCTION("""COMPUTED_VALUE"""),"山岡 陽子様") -> 山岡 陽子様 | AG3: =IFERROR(__xludf.DUMMYFUNCTION("""COMPUTED_VALUE"""),"妻") -> 妻 | AI3: =IFERROR(__xludf.DUMMYFUNCTION("""COMPUTED_VALUE"""),"別居") -> 別居 | AJ3: =IFERROR(__xludf.DUMMYFUNCTION("""COMPUTED_VALUE"""),"介護する") -> 介護する | AK3: =IFERROR(__xludf.DUMMYFUNCTION("""COMPUTED_VALUE"""),"有") -> 有 | AL3: =IFERROR(__xludf.DUMMYFUNCTION("""COMPUTED_VALUE"""),"090-7679-9851") -> 090-7679-9851 | AM3: =IFERROR(__xludf.DUMMYFUNCTION("""COMPUTED_VALUE"""),"KP") -> KP | AW3: =IFERROR(__xludf.DUMMYFUNCTION("""COMPUTED_VALUE"""),"入力") -> 入力 | AX3: =IFERROR(__xludf.DUMMYFUNCTION("""COMPUTED_VALUE"""),"家族同居") -> 家族同居 | AY3: =IFERROR(__xludf.DUMMYFUNCTION("""COMPUTED_VALUE"""),"一戸建て") -> 一戸建て | AZ3: =IFERROR(__xludf.DUMMYFUNCTION("""COMPUTED_VALUE"""),"エレベーター有") -> エレベーター有 | BA3: =IFERROR(__xludf.DUMMYFUNCTION("""COMPUTED_VALUE"""),"所有") -> 所有 | BB3: =IFERROR(__xludf.DUMMYFUNCTION("""COMPUTED_VALUE"""),"有") -> 有 | BC3: =IFERROR(__xludf.DUMMYFUNCTION("""COMPUTED_VALUE"""),"有") -> 有 | BD3: =IFERROR(__xludf.DUMMYFUNCTION("""COMPUTED_VALUE"""),"洋式") -> 洋式 | BG3: =IFERROR(__xludf.DUMMYFUNCTION("""COMPUTED_VALUE"""),"有") -> 有 | BH3: =IFERROR(__xludf.DUMMYFUNCTION("""COMPUTED_VALUE"""),"手すり無") -> 手すり無 | BI3: =IFERROR(__xludf.DUMMYFUNCTION("""COMPUTED_VALUE"""),"ベッド") -> ベッド | BJ3: =IFERROR(__xludf.DUMMYFUNCTION("""COMPUTED_VALUE"""),"無") -> 無 | BK3: =IFERROR(__xludf.DUMMYFUNCTION("""COMPUTED_VALUE"""),"無") -> 無 | BL3: =IFERROR(__xludf.DUMMYFUNCTION("""COMPUTED_VALUE"""),"無") -> 無 | BO3: =IFERROR(__xludf.DUMMYFUNCTION("""COMPUTED_VALUE"""),"入力") -> 入力 | BP3: =IFERROR(__xludf.DUMMYFUNCTION("""COMPUTED_VALUE"""),"訪問介護 , 訪問看護 , 通所介護") -> 訪問介護 , 訪問看護 , 通所介護 | BQ3: =IFERROR(__xludf.DUMMYFUNCTION("""COMPUTED_VALUE"""),"車いす , 特殊寝台 , 特殊寝台付属品 , 手すり") -> 車いす , 特殊寝台 , 特殊寝台付属品 , 手すり | BS3: =IFERROR(__xludf.DUMMYFUNCTION("""COMPUTED_VALUE"""),"食事支援 , 排泄支援 , リネンリース , 洗濯 , 喀痰吸引") -> 食事支援 , 排泄支援 , リネンリース , 洗濯 , 喀痰吸引 | BT3: =IFERROR(__xludf.DUMMYFUNCTION("""COMPUTED_VALUE"""),"デイサービス等大人数のところは積極的にはいかない。") -> デイサービス等大人数のところは積極的にはいかない。 | BW3: =IFERROR(__xludf.DUMMYFUNCTION("""COMPUTED_VALUE"""),"入力") -> 入力 | BX3: =IFERROR(__xludf.DUMMYFUNCTION("""COMPUTED_VALUE"""),"誤嚥性肺炎") -> 誤嚥性肺炎 | BY3: =IFERROR(__xludf.DUMMYFUNCTION("""COMPUTED_VALUE"""),"令和6年7月5日") -> 令和6年7月5日 | BZ3: =IFERROR(__xludf.DUMMYFUNCTION("""COMPUTED_VALUE"""),"脳リンパ腫") -> 脳リンパ腫 | CA3: =IFERROR(__xludf.DUMMYFUNCTION("""COMPUTED_VALUE"""),"令和5年11月頃") -> 令和5年11月頃 | CJ3: =IFERROR(__xludf.DUMMYFUNCTION("""COMPUTED_VALUE"""),"発熱があれば武内病院を受診することとなっている。武内病院 血液内科 塚田先生") -> 発熱があれば武内病院を受診することとなっている。武内病院 血液内科 塚田先生 | CS3: =IFERROR(__xludf.DUMMYFUNCTION("""COMPUTED_VALUE"""),"既往にリウマチや腸閉塞（手術済み）があるが現在は特に問題なし。") -> 既往にリウマチや腸閉塞（手術済み）があるが現在は特に問題なし。 | CT3: =IFERROR(__xludf.DUMMYFUNCTION("""COMPUTED_VALUE"""),"服薬管理は看護師が行っている。 退院後は、ローレル薬局を契約。 袋を手渡しすることで、ご自身で袋を開封して内服できる。") -> 服薬管理は看護師が行っている。 退院後は、ローレル薬局を契約。 袋を手渡しすることで、ご自身で袋を開封して内服できる。 | CX3: =IFERROR(__xludf.DUMMYFUNCTION("""COMPUTED_VALUE"""),"入力") -> 入力 | CY3: =IFERROR(__xludf.DUMMYFUNCTION("""COMPUTED_VALUE"""),"無") -> 無 | CZ3: =IFERROR(__xludf.DUMMYFUNCTION("""COMPUTED_VALUE"""),"無") -> 無 | DA3: =IFERROR(__xludf.DUMMYFUNCTION("""COMPUTED_VALUE"""),"無") -> 無 | DB3: =IFERROR(__xludf.DUMMYFUNCTION("""COMPUTED_VALUE"""),"右上肢、右下肢") -> 右上肢、右下肢 | DC3: =IFERROR(__xludf.DUMMYFUNCTION("""COMPUTED_VALUE"""),"無") -> 無 | DD3: =IFERROR(__xludf.DUMMYFUNCTION("""COMPUTED_VALUE"""),0) -> 0 | DE3: =IFERROR(__xludf.DUMMYFUNCTION("""COMPUTED_VALUE"""),0) -> 0 | DF3: =IFERROR(__xludf.DUMMYFUNCTION("""COMPUTED_VALUE"""),"大きい字は可") -> 大きい字は可 | DG3: =IFERROR(__xludf.DUMMYFUNCTION("""COMPUTED_VALUE"""),"有") -> 有 | DH3: =IFERROR(__xludf.DUMMYFUNCTION("""COMPUTED_VALUE"""),"大きい声は可") -> 大きい声は可 | DI3: =IFERROR(__xludf.DUMMYFUNCTION("""COMPUTED_VALUE"""),"有") -> 有 | DJ3: =IFERROR(__xludf.DUMMYFUNCTION("""COMPUTED_VALUE"""),"脳リンパ腫の影響で右半身麻痺及び軽度の失語症が見られる。視力は大きな問題はないものの、難聴があり大きな声で話す必要がある。 痰が多く、常にゴロゴロしている状況であり、ご自身で排痰を行うことができないものの、吸引はやや拒否がある。 ここ最近、痰の量が増えており、吸引の拒否も少なくなっている。") -> 脳リンパ腫の影響で右半身麻痺及び軽度の失語症が見られる。視力は大きな問題はないものの、難聴があり大きな声で話す必要がある。 痰が多く、常にゴロゴロしている状況であり、ご自身で排痰を行うことができないものの、吸引はやや拒否がある。 ここ最近、痰の量が増えており、吸引の拒否も少なくなっている。 | DL3: =IFERROR(__xludf.DUMMYFUNCTION("""COMPUTED_VALUE"""),"入力") -> 入力 | DM3: =IFERROR(__xludf.DUMMYFUNCTION("""COMPUTED_VALUE"""),"有") -> 有 | DN3: =IFERROR(__xludf.DUMMYFUNCTION("""COMPUTED_VALUE"""),"軽度") -> 軽度 | DO3: =IFERROR(__xludf.DUMMYFUNCTION("""COMPUTED_VALUE"""),"無") -> 無 | DP3: =IFERROR(__xludf.DUMMYFUNCTION("""COMPUTED_VALUE"""),"やや不自由") -> やや不自由 | DQ3: =IFERROR(__xludf.DUMMYFUNCTION("""COMPUTED_VALUE"""),"やや不自由") -> やや不自由 | DR3: =IFERROR(__xludf.DUMMYFUNCTION("""COMPUTED_VALUE"""),"失語症があり認知機能の精査は困難。") -> 失語症があり認知機能の精査は困難。 | DU3: =IFERROR(__xludf.DUMMYFUNCTION("""COMPUTED_VALUE"""),"入力") -> 入力 | DV3: =IFERROR(__xludf.DUMMYFUNCTION("""COMPUTED_VALUE"""),"何かにつかまればできる") -> 何かにつかまればできる | DW3: =IFERROR(__xludf.DUMMYFUNCTION("""COMPUTED_VALUE"""),"何かにつかまればできる") -> 何かにつかまればできる | DX3: =IFERROR(__xludf.DUMMYFUNCTION("""COMPUTED_VALUE"""),"自分の手で支えればできる") -> 自分の手で支えればできる | DY3: =IFERROR(__xludf.DUMMYFUNCTION("""COMPUTED_VALUE"""),"何かにつかまればできる") -> 何かにつかまればできる | DZ3: =IFERROR(__xludf.DUMMYFUNCTION("""COMPUTED_VALUE"""),"何か支えがあればできる") -> 何か支えがあればできる | EA3: =IFERROR(__xludf.DUMMYFUNCTION("""COMPUTED_VALUE"""),"見守り") -> 見守り | EB3: =IFERROR(__xludf.DUMMYFUNCTION("""COMPUTED_VALUE"""),"見守り") -> 見守り | EC3: =IFERROR(__xludf.DUMMYFUNCTION("""COMPUTED_VALUE"""),"独歩") -> 独歩 | ED3: =IFERROR(__xludf.DUMMYFUNCTION("""COMPUTED_VALUE"""),"一部介助") -> 一部介助 | EE3: =IFERROR(__xludf.DUMMYFUNCTION("""COMPUTED_VALUE"""),"車椅子") -> 車椅子 | EF3: =IFERROR(__xludf.DUMMYFUNCTION("""COMPUTED_VALUE"""),"基本動作はご自身で行うことが可能。ベッドからトイレまでは手すりを設置しており、不安定ではあるもののご自身で移動できている。 長距離の移動は車いすを使用。現在訪問リハビリを受けており歩行器での歩行訓練を行っている。") -> 基本動作はご自身で行うことが可能。ベッドからトイレまでは手すりを設置しており、不安定ではあるもののご自身で移動できている。 長距離の移動は車いすを使用。現在訪問リハビリを受けており歩行器での歩行訓練を行っている。 | EH3: =IFERROR(__xludf.DUMMYFUNCTION("""COMPUTED_VALUE"""),"入力") -> 入力 | EI3: =IFERROR(__xludf.DUMMYFUNCTION("""COMPUTED_VALUE"""),"入力") -> 入力 | EJ3: =IFERROR(__xludf.DUMMYFUNCTION("""COMPUTED_VALUE"""),"経口摂取") -> 経口摂取 | EK3: =IFERROR(__xludf.DUMMYFUNCTION("""COMPUTED_VALUE"""),"自立") -> 自立 | EL3: =IFERROR(__xludf.DUMMYFUNCTION("""COMPUTED_VALUE"""),"見守り等が必要") -> 見守り等が必要 | EM3: =IFERROR(__xludf.DUMMYFUNCTION("""COMPUTED_VALUE"""),"ペースト") -> ペースト | EN3: =IFERROR(__xludf.DUMMYFUNCTION("""COMPUTED_VALUE"""),"ペースト") -> ペースト | EO3: =IFERROR(__xludf.DUMMYFUNCTION("""COMPUTED_VALUE"""),"有") -> 有 | EP3: =IFERROR(__xludf.DUMMYFUNCTION("""COMPUTED_VALUE"""),"有") -> 有 | EQ3: =IFERROR(__xludf.DUMMYFUNCTION("""COMPUTED_VALUE"""),"スプーン") -> スプーン | ER3: =IFERROR(__xludf.DUMMYFUNCTION("""COMPUTED_VALUE"""),"食事制限があり、ナッツ類とブルーチーズは禁止。 ここ最近は、痰量の増加に伴い嚥下機能の低下があり食事の前後で痰の吸引を行う必要がある。ご自身で摂取することは可能。 加藤先生から絶食の指示が出たが、ご家族様の強い希望で食事を食べてほしいという理由から、食事形態を落として食事して頂いている。") -> 食事制限があり、ナッツ類とブルーチーズは禁止。 ここ最近は、痰量の増加に伴い嚥下機能の低下があり食事の前後で痰の吸引を行う必要がある。ご自身で摂取することは可能。 加藤先生から絶食の指示が出たが、ご家族様の強い希望で食事を食べてほしいという理由から、食事形態を落として食事して頂いている。 | ET3: =IFERROR(__xludf.DUMMYFUNCTION("""COMPUTED_VALUE"""),"入力") -> 入力 | EU3: =IFERROR(__xludf.DUMMYFUNCTION("""COMPUTED_VALUE"""),"見守り") -> 見守り | EW3: =IFERROR(__xludf.DUMMYFUNCTION("""COMPUTED_VALUE"""),"無") -> 無 | EZ3: =IFERROR(__xludf.DUMMYFUNCTION("""COMPUTED_VALUE"""),"促しが必要であるが、洗面所で口腔ケアが可能。 訪問リハビリSTより、誤嚥性肺炎を防ぐためにも口腔ケアはきちんと行ったほうがよいと助言有。") -> 促しが必要であるが、洗面所で口腔ケアが可能。 訪問リハビリSTより、誤嚥性肺炎を防ぐためにも口腔ケアはきちんと行ったほうがよいと助言有。 | FB3: =IFERROR(__xludf.DUMMYFUNCTION("""COMPUTED_VALUE"""),"入力") -> 入力 | FC3: =IFERROR(__xludf.DUMMYFUNCTION("""COMPUTED_VALUE"""),"一部介助") -> 一部介助 | FD3: =IFERROR(__xludf.DUMMYFUNCTION("""COMPUTED_VALUE"""),"一般浴") -> 一般浴 | FE3: =IFERROR(__xludf.DUMMYFUNCTION("""COMPUTED_VALUE"""),"無") -> 無 | FG3: =IFERROR(__xludf.DUMMYFUNCTION("""COMPUTED_VALUE"""),"一部介助") -> 一部介助 | FH3: =IFERROR(__xludf.DUMMYFUNCTION("""COMPUTED_VALUE"""),"一部介助") -> 一部介助 | FI3: =IFERROR(__xludf.DUMMYFUNCTION("""COMPUTED_VALUE"""),"入浴の拒否があり、現在はご家族様が入浴時間に付き添って促して頂いている。") -> 入浴の拒否があり、現在はご家族様が入浴時間に付き添って促して頂いている。 | FK3: =IFERROR(__xludf.DUMMYFUNCTION("""COMPUTED_VALUE"""),"入力") -> 入力 | FL3: =IFERROR(__xludf.DUMMYFUNCTION("""COMPUTED_VALUE"""),"自立") -> 自立 | FM3: =IFERROR(__xludf.DUMMYFUNCTION("""COMPUTED_VALUE"""),"有") -> 有 | FN3: =IFERROR(__xludf.DUMMYFUNCTION("""COMPUTED_VALUE"""),"有") -> 有 | FO3: =IFERROR(__xludf.DUMMYFUNCTION("""COMPUTED_VALUE"""),"有") -> 有 | FP3: =IFERROR(__xludf.DUMMYFUNCTION("""COMPUTED_VALUE"""),"有") -> 有 | FQ3: =IFERROR(__xludf.DUMMYFUNCTION("""COMPUTED_VALUE"""),"軟便") -> 軟便 | FR3: =IFERROR(__xludf.DUMMYFUNCTION("""COMPUTED_VALUE"""),"トイレ") -> トイレ | FS3: =IFERROR(__xludf.DUMMYFUNCTION("""COMPUTED_VALUE"""),"トイレ") -> トイレ | FT3: =IFERROR(__xludf.DUMMYFUNCTION("""COMPUTED_VALUE"""),"リハビリパンツ , 小パット") -> リハビリパンツ , 小パット | FU3: =IFERROR(__xludf.DUMMYFUNCTION("""COMPUTED_VALUE"""),"排泄はご自身で可能。失禁があるがご自身で交換は可能だが、汚物処理は不可能。") -> 排泄はご自身で可能。失禁があるがご自身で交換は可能だが、汚物処理は不可能。 | FX3: =IFERROR(__xludf.DUMMYFUNCTION("""COMPUTED_VALUE"""),"入力") -> 入力 | FY3: =IFERROR(__xludf.DUMMYFUNCTION("""COMPUTED_VALUE"""),"全介助") -> 全介助 | FZ3: =IFERROR(__xludf.DUMMYFUNCTION("""COMPUTED_VALUE"""),"全介助") -> 全介助 | GA3: =IFERROR(__xludf.DUMMYFUNCTION("""COMPUTED_VALUE"""),"全介助") -> 全介助 | GB3: =IFERROR(__xludf.DUMMYFUNCTION("""COMPUTED_VALUE"""),"全介助") -> 全介助 | GC3: =IFERROR(__xludf.DUMMYFUNCTION("""COMPUTED_VALUE"""),"全介助") -> 全介助 | GD3: =IFERROR(__xludf.DUMMYFUNCTION("""COMPUTED_VALUE"""),"施設内のサービスを利用。") -> 施設内のサービスを利用。 | GG3: =IFERROR(__xludf.DUMMYFUNCTION("""COMPUTED_VALUE"""),"食事前後の痰吸引のため毎食訪問看護の支援が必要な状況であるが、自己負担額が高額になることに不安があるものの、３食ご飯を食べてほしい。等矛盾な発言も見られる。ご家族様は全く悪い方ではありませんが、特に料金面で細かい性格をしているため、都度説明を要す場面も多い。") -> 食事前後の痰吸引のため毎食訪問看護の支援が必要な状況であるが、自己負担額が高額になることに不安があるものの、３食ご飯を食べてほしい。等矛盾な発言も見られる。ご家族様は全く悪い方ではありませんが、特に料金面で細かい性格をしているため、都度説明を要す場面も多い。 | GH3: =IFERROR(__xludf.DUMMYFUNCTION("""COMPUTED_VALUE"""),30) -> 30
C4: =IFERROR(__xludf.DUMMYFUNCTION("""COMPUTED_VALUE"""),"樋口 智子") -> 樋口 智子 | D4: =IFERROR(__xludf.DUMMYFUNCTION("""COMPUTED_VALUE"""),"2010031305") -> 2010031305 | I4: =IFERROR(__xludf.DUMMYFUNCTION("""COMPUTED_VALUE"""),45474) -> 45474 | J4: =IFERROR(__xludf.DUMMYFUNCTION("""COMPUTED_VALUE"""),"山川 和輝") -> 山川 和輝 | K4: =IFERROR(__xludf.DUMMYFUNCTION("""COMPUTED_VALUE"""),"更新") -> 更新 | L4: =IFERROR(__xludf.DUMMYFUNCTION("""COMPUTED_VALUE"""),"本人の居室") -> 本人の居室 | M4: =IFERROR(__xludf.DUMMYFUNCTION("""COMPUTED_VALUE"""),"平成28年8月28日にサービス付き高齢者向け住宅 安濃津ろまんに入居される。") -> 平成28年8月28日にサービス付き高齢者向け住宅 安濃津ろまんに入居される。 | N4: =IFERROR(__xludf.DUMMYFUNCTION("""COMPUTED_VALUE"""),"ここで安定した生活を送らせてもらってます。動けるようになってきたので嬉しいです。") -> ここで安定した生活を送らせてもらってます。動けるようになってきたので嬉しいです。 | O4: =IFERROR(__xludf.DUMMYFUNCTION("""COMPUTED_VALUE"""),"転倒や怪我をしないように気をつけて、安全に生活を続けてほしいと思っています。") -> 転倒や怪我をしないように気をつけて、安全に生活を続けてほしいと思っています。 | Q4: =IFERROR(__xludf.DUMMYFUNCTION("""COMPUTED_VALUE"""),"入力") -> 入力 | R4: =IFERROR(__xludf.DUMMYFUNCTION("""COMPUTED_VALUE"""),"要介護１") -> 要介護１ | S4: =IFERROR(__xludf.DUMMYFUNCTION("""COMPUTED_VALUE"""),"令和6年7月16日") -> 令和6年7月16日 | T4: =IFERROR(__xludf.DUMMYFUNCTION("""COMPUTED_VALUE"""),"令和6年8月1日") -> 令和6年8月1日 | U4: =IFERROR(__xludf.DUMMYFUNCTION("""COMPUTED_VALUE"""),"令和9年7月31日") -> 令和9年7月31日 | V4: =IFERROR(__xludf.DUMMYFUNCTION("""COMPUTED_VALUE"""),"１割負担") -> １割負担 | W4: =IFERROR(__xludf.DUMMYFUNCTION("""COMPUTED_VALUE"""),"後期高齢者医療保険") -> 後期高齢者医療保険 | X4: =IFERROR(__xludf.DUMMYFUNCTION("""COMPUTED_VALUE"""),"無") -> 無 | Z4: =IFERROR(__xludf.DUMMYFUNCTION("""COMPUTED_VALUE"""),"無") -> 無 | AA4: =IFERROR(__xludf.DUMMYFUNCTION("""COMPUTED_VALUE"""),"無") -> 無 | AB4: =IFERROR(__xludf.DUMMYFUNCTION("""COMPUTED_VALUE"""),"A2") -> A2 | AC4: =IFERROR(__xludf.DUMMYFUNCTION("""COMPUTED_VALUE"""),"Ⅱa") -> Ⅱa | AE4: =IFERROR(__xludf.DUMMYFUNCTION("""COMPUTED_VALUE"""),"入力") -> 入力 | AF4: =IFERROR(__xludf.DUMMYFUNCTION("""COMPUTED_VALUE"""),"山川 康子") -> 山川 康子 | AG4: =IFERROR(__xludf.DUMMYFUNCTION("""COMPUTED_VALUE"""),"長女") -> 長女 | AI4: =IFERROR(__xludf.DUMMYFUNCTION("""COMPUTED_VALUE"""),"別居") -> 別居 | AJ4: =IFERROR(__xludf.DUMMYFUNCTION("""COMPUTED_VALUE"""),"介護する") -> 介護する | AL4: =IFERROR(__xludf.DUMMYFUNCTION("""COMPUTED_VALUE"""),"090-8866-0346") -> 090-8866-0346 | AM4: =IFERROR(__xludf.DUMMYFUNCTION("""COMPUTED_VALUE"""),"KP") -> KP | AN4: =IFERROR(__xludf.DUMMYFUNCTION("""COMPUTED_VALUE"""),"樋口 徹") -> 樋口 徹 | AO4: =IFERROR(__xludf.DUMMYFUNCTION("""COMPUTED_VALUE"""),"長男") -> 長男 | AQ4: =IFERROR(__xludf.DUMMYFUNCTION("""COMPUTED_VALUE"""),"別居") -> 別居 | AR4: =IFERROR(__xludf.DUMMYFUNCTION("""COMPUTED_VALUE"""),"介護しない") -> 介護しない | AT4: =IFERROR(__xludf.DUMMYFUNCTION("""COMPUTED_VALUE"""),"059-246-8900") -> 059-246-8900 | AW4: =IFERROR(__xludf.DUMMYFUNCTION("""COMPUTED_VALUE"""),"入力") -> 入力 | AX4: =IFERROR(__xludf.DUMMYFUNCTION("""COMPUTED_VALUE"""),"一人暮らし") -> 一人暮らし | AY4: =IFERROR(__xludf.DUMMYFUNCTION("""COMPUTED_VALUE"""),"集合住宅") -> 集合住宅 | AZ4: =IFERROR(__xludf.DUMMYFUNCTION("""COMPUTED_VALUE"""),"エレベーター有") -> エレベーター有 | BA4: =IFERROR(__xludf.DUMMYFUNCTION("""COMPUTED_VALUE"""),"賃貸") -> 賃貸 | BB4: =IFERROR(__xludf.DUMMYFUNCTION("""COMPUTED_VALUE"""),"有") -> 有 | BC4: =IFERROR(__xludf.DUMMYFUNCTION("""COMPUTED_VALUE"""),"有") -> 有 | BD4: =IFERROR(__xludf.DUMMYFUNCTION("""COMPUTED_VALUE"""),"ウォシュレット") -> ウォシュレット | BG4: =IFERROR(__xludf.DUMMYFUNCTION("""COMPUTED_VALUE"""),"無") -> 無 | BI4: =IFERROR(__xludf.DUMMYFUNCTION("""COMPUTED_VALUE"""),"リクライニングベッド") -> リクライニングベッド | BJ4: =IFERROR(__xludf.DUMMYFUNCTION("""COMPUTED_VALUE"""),"無") -> 無 | BK4: =IFERROR(__xludf.DUMMYFUNCTION("""COMPUTED_VALUE"""),"無") -> 無 | BL4: =IFERROR(__xludf.DUMMYFUNCTION("""COMPUTED_VALUE"""),"無") -> 無 | BO4: =IFERROR(__xludf.DUMMYFUNCTION("""COMPUTED_VALUE"""),"入力") -> 入力 | BP4: =IFERROR(__xludf.DUMMYFUNCTION("""COMPUTED_VALUE"""),"訪問介護 , 訪問看護") -> 訪問介護 , 訪問看護 | BQ4: =IFERROR(__xludf.DUMMYFUNCTION("""COMPUTED_VALUE"""),"車いす") -> 車いす | BR4: =IFERROR(__xludf.DUMMYFUNCTION("""COMPUTED_VALUE"""),"福祉用具（特殊寝台）自費貸与") -> 福祉用具（特殊寝台）自費貸与 | BS4: =IFERROR(__xludf.DUMMYFUNCTION("""COMPUTED_VALUE"""),"食事支援 , リネンリース , 洗濯") -> 食事支援 , リネンリース , 洗濯 | BT4: =IFERROR(__xludf.DUMMYFUNCTION("""COMPUTED_VALUE"""),"食事中にホールにて他の利用者とお話しされている様子はあるが、基本居室に引きこもった生活となっている。") -> 食事中にホールにて他の利用者とお話しされている様子はあるが、基本居室に引きこもった生活となっている。 | BW4: =IFERROR(__xludf.DUMMYFUNCTION("""COMPUTED_VALUE"""),"入力") -> 入力 | BX4: =IFERROR(__xludf.DUMMYFUNCTION("""COMPUTED_VALUE"""),"逆流性食道炎") -> 逆流性食道炎 | BY4: =IFERROR(__xludf.DUMMYFUNCTION("""COMPUTED_VALUE"""),"平成22年2月5日") -> 平成22年2月5日 | BZ4: =IFERROR(__xludf.DUMMYFUNCTION("""COMPUTED_VALUE"""),"慢性胃炎") -> 慢性胃炎 | CA4: =IFERROR(__xludf.DUMMYFUNCTION("""COMPUTED_VALUE"""),"平成22年2月5日") -> 平成22年2月5日 | CB4: =IFERROR(__xludf.DUMMYFUNCTION("""COMPUTED_VALUE"""),"抑うつ神経症") -> 抑うつ神経症 | CC4: =IFERROR(__xludf.DUMMYFUNCTION("""COMPUTED_VALUE"""),"平成19年6月25日") -> 平成19年6月25日 | CD4: =IFERROR(__xludf.DUMMYFUNCTION("""COMPUTED_VALUE"""),"高血圧症") -> 高血圧症 | CE4: =IFERROR(__xludf.DUMMYFUNCTION("""COMPUTED_VALUE"""),"平成14年2月19日") -> 平成14年2月19日 | CJ4: =IFERROR(__xludf.DUMMYFUNCTION("""COMPUTED_VALUE"""),"現在は往診を受けており、通院は行っていない。") -> 現在は往診を受けており、通院は行っていない。 | CS4: =IFERROR(__xludf.DUMMYFUNCTION("""COMPUTED_VALUE"""),"特に大きな病気は見られていない。") -> 特に大きな病気は見られていない。 | CT4: =IFERROR(__xludf.DUMMYFUNCTION("""COMPUTED_VALUE"""),"高血圧症等を服薬されている。ローレル薬局と看護師で服薬を管理して毎食時に袋を提供すると自身で開けて飲まれる。") -> 高血圧症等を服薬されている。ローレル薬局と看護師で服薬を管理して毎食時に袋を提供すると自身で開けて飲まれる。 | CX4: =IFERROR(__xludf.DUMMYFUNCTION("""COMPUTED_VALUE"""),"入力") -> 入力 | CY4: =IFERROR(__xludf.DUMMYFUNCTION("""COMPUTED_VALUE"""),"無") -> 無 | CZ4: =IFERROR(__xludf.DUMMYFUNCTION("""COMPUTED_VALUE"""),"無") -> 無 | DA4: =IFERROR(__xludf.DUMMYFUNCTION("""COMPUTED_VALUE"""),"無") -> 無 | DB4: =IFERROR(__xludf.DUMMYFUNCTION("""COMPUTED_VALUE"""),"無") -> 無 | DC4: =IFERROR(__xludf.DUMMYFUNCTION("""COMPUTED_VALUE"""),"無") -> 無 | DF4: =IFERROR(__xludf.DUMMYFUNCTION("""COMPUTED_VALUE"""),"正常") -> 正常 | DH4: =IFERROR(__xludf.DUMMYFUNCTION("""COMPUTED_VALUE"""),"正常") -> 正常 | DJ4: =IFERROR(__xludf.DUMMYFUNCTION("""COMPUTED_VALUE"""),"特に大きな問題はなし。") -> 特に大きな問題はなし。 | DL4: =IFERROR(__xludf.DUMMYFUNCTION("""COMPUTED_VALUE"""),"入力") -> 入力 | DM4: =IFERROR(__xludf.DUMMYFUNCTION("""COMPUTED_VALUE"""),"無") -> 無 | DO4: =IFERROR(__xludf.DUMMYFUNCTION("""COMPUTED_VALUE"""),"無") -> 無 | DP4: =IFERROR(__xludf.DUMMYFUNCTION("""COMPUTED_VALUE"""),"可能") -> 可能 | DQ4: =IFERROR(__xludf.DUMMYFUNCTION("""COMPUTED_VALUE"""),"可能") -> 可能 | DR4: =IFERROR(__xludf.DUMMYFUNCTION("""COMPUTED_VALUE"""),"年相応の物忘れはあるものの、特に日常生活に支障が出るほどではない。") -> 年相応の物忘れはあるものの、特に日常生活に支障が出るほどではない。 | DU4: =IFERROR(__xludf.DUMMYFUNCTION("""COMPUTED_VALUE"""),"入力") -> 入力 | DV4: =IFERROR(__xludf.DUMMYFUNCTION("""COMPUTED_VALUE"""),"何かにつかまればできる") -> 何かにつかまればできる | DW4: =IFERROR(__xludf.DUMMYFUNCTION("""COMPUTED_VALUE"""),"何かにつかまればできる") -> 何かにつかまればできる | DX4: =IFERROR(__xludf.DUMMYFUNCTION("""COMPUTED_VALUE"""),"自分の手で支えればできる") -> 自分の手で支えればできる | DY4: =IFERROR(__xludf.DUMMYFUNCTION("""COMPUTED_VALUE"""),"何かにつかまればできる") -> 何かにつかまればできる | DZ4: =IFERROR(__xludf.DUMMYFUNCTION("""COMPUTED_VALUE"""),"何か支えがあればできる") -> 何か支えがあればできる | EA4: =IFERROR(__xludf.DUMMYFUNCTION("""COMPUTED_VALUE"""),"自立") -> 自立 | EB4: =IFERROR(__xludf.DUMMYFUNCTION("""COMPUTED_VALUE"""),"自立") -> 自立 | EC4: =IFERROR(__xludf.DUMMYFUNCTION("""COMPUTED_VALUE"""),"独歩") -> 独歩 | ED4: =IFERROR(__xludf.DUMMYFUNCTION("""COMPUTED_VALUE"""),"全介助") -> 全介助 | EE4: =IFERROR(__xludf.DUMMYFUNCTION("""COMPUTED_VALUE"""),"車椅子") -> 車椅子 | EF4: =IFERROR(__xludf.DUMMYFUNCTION("""COMPUTED_VALUE"""),"居室内の移動は独歩、伝い歩行で移動。円背が強くあり転倒のリスクはある。居室外は車いすを使用している。") -> 居室内の移動は独歩、伝い歩行で移動。円背が強くあり転倒のリスクはある。居室外は車いすを使用している。 | EH4: =IFERROR(__xludf.DUMMYFUNCTION("""COMPUTED_VALUE"""),"入力") -> 入力 | EI4: =IFERROR(__xludf.DUMMYFUNCTION("""COMPUTED_VALUE"""),"入力") -> 入力 | EJ4: =IFERROR(__xludf.DUMMYFUNCTION("""COMPUTED_VALUE"""),"経口摂取") -> 経口摂取 | EK4: =IFERROR(__xludf.DUMMYFUNCTION("""COMPUTED_VALUE"""),"自立") -> 自立 | EL4: =IFERROR(__xludf.DUMMYFUNCTION("""COMPUTED_VALUE"""),"できる") -> できる | EM4: =IFERROR(__xludf.DUMMYFUNCTION("""COMPUTED_VALUE"""),"普通") -> 普通 | EN4: =IFERROR(__xludf.DUMMYFUNCTION("""COMPUTED_VALUE"""),"普通") -> 普通 | EO4: =IFERROR(__xludf.DUMMYFUNCTION("""COMPUTED_VALUE"""),"無") -> 無 | EP4: =IFERROR(__xludf.DUMMYFUNCTION("""COMPUTED_VALUE"""),"無") -> 無 | EQ4: =IFERROR(__xludf.DUMMYFUNCTION("""COMPUTED_VALUE"""),"箸 , スプーン") -> 箸 , スプーン | ER4: =IFERROR(__xludf.DUMMYFUNCTION("""COMPUTED_VALUE"""),"特に問題なし。") -> 特に問題なし。 | ET4: =IFERROR(__xludf.DUMMYFUNCTION("""COMPUTED_VALUE"""),"入力") -> 入力 | EU4: =IFERROR(__xludf.DUMMYFUNCTION("""COMPUTED_VALUE"""),"自立") -> 自立 | EW4: =IFERROR(__xludf.DUMMYFUNCTION("""COMPUTED_VALUE"""),"有") -> 有 | EZ4: =IFERROR(__xludf.DUMMYFUNCTION("""COMPUTED_VALUE"""),"義歯は不明。") -> 義歯は不明。 | FB4: =IFERROR(__xludf.DUMMYFUNCTION("""COMPUTED_VALUE"""),"入力") -> 入力 | FC4: =IFERROR(__xludf.DUMMYFUNCTION("""COMPUTED_VALUE"""),"一部介助") -> 一部介助 | FD4: =IFERROR(__xludf.DUMMYFUNCTION("""COMPUTED_VALUE"""),"一般浴") -> 一般浴 | FE4: =IFERROR(__xludf.DUMMYFUNCTION("""COMPUTED_VALUE"""),"無") -> 無 | FG4: =IFERROR(__xludf.DUMMYFUNCTION("""COMPUTED_VALUE"""),"見守り") -> 見守り | FH4: =IFERROR(__xludf.DUMMYFUNCTION("""COMPUTED_VALUE"""),"見守り") -> 見守り | FI4: =IFERROR(__xludf.DUMMYFUNCTION("""COMPUTED_VALUE"""),"入浴はヘルパーステーションで行っている。") -> 入浴はヘルパーステーションで行っている。 | FK4: =IFERROR(__xludf.DUMMYFUNCTION("""COMPUTED_VALUE"""),"入力") -> 入力 | FL4: =IFERROR(__xludf.DUMMYFUNCTION("""COMPUTED_VALUE"""),"自立") -> 自立 | FM4: =IFERROR(__xludf.DUMMYFUNCTION("""COMPUTED_VALUE"""),"有") -> 有 | FN4: =IFERROR(__xludf.DUMMYFUNCTION("""COMPUTED_VALUE"""),"無") -> 無 | FO4: =IFERROR(__xludf.DUMMYFUNCTION("""COMPUTED_VALUE"""),"有") -> 有 | FP4: =IFERROR(__xludf.DUMMYFUNCTION("""COMPUTED_VALUE"""),"無") -> 無 | FQ4: =IFERROR(__xludf.DUMMYFUNCTION("""COMPUTED_VALUE"""),"普通便") -> 普通便 | FR4: =IFERROR(__xludf.DUMMYFUNCTION("""COMPUTED_VALUE"""),"トイレ") -> トイレ | FS4: =IFERROR(__xludf.DUMMYFUNCTION("""COMPUTED_VALUE"""),"トイレ") -> トイレ | FT4: =IFERROR(__xludf.DUMMYFUNCTION("""COMPUTED_VALUE"""),"リハビリパンツ , 小パット") -> リハビリパンツ , 小パット | FU4: =IFERROR(__xludf.DUMMYFUNCTION("""COMPUTED_VALUE"""),"排泄は失禁なくご自身で行えている。") -> 排泄は失禁なくご自身で行えている。 | FX4: =IFERROR(__xludf.DUMMYFUNCTION("""COMPUTED_VALUE"""),"入力") -> 入力 | FY4: =IFERROR(__xludf.DUMMYFUNCTION("""COMPUTED_VALUE"""),"全介助") -> 全介助 | FZ4: =IFERROR(__xludf.DUMMYFUNCTION("""COMPUTED_VALUE"""),"全介助") -> 全介助 | GA4: =IFERROR(__xludf.DUMMYFUNCTION("""COMPUTED_VALUE"""),"全介助") -> 全介助 | GB4: =IFERROR(__xludf.DUMMYFUNCTION("""COMPUTED_VALUE"""),"全介助") -> 全介助 | GC4: =IFERROR(__xludf.DUMMYFUNCTION("""COMPUTED_VALUE"""),"全介助") -> 全介助 | GG4: =IFERROR(__xludf.DUMMYFUNCTION("""COMPUTED_VALUE"""),"特になし。") -> 特になし。 | GH4: =IFERROR(__xludf.DUMMYFUNCTION("""COMPUTED_VALUE"""),40) -> 40
